Workbook

Sheet CF BEST
A1: ФАКТ | B1: Денег на счету | C1: Нал | D1: Баланс на данный момент в безнале | F1: Альфа | G1: ОТП | H1: Совком | J1: =I2+H2+G2-B2 -> -471767.88 | M1: 1371350 | N1: долг рост через альфарм
B2: =SUMIFS(C9:C2880, B9:B2880, "оплачено", E9:E2880, "<>наличные")-SUMIFS(D9:D2880, B9:B2880, "оплачено", E9:E2880, "<>наличные") -> 2200319.3 | C2: =SUMIFS(C9:C2880, B9:B2880, "оплачено", E9:E2880, "наличные")-SUMIFS(D9:D2880, B9:B2880, "оплачено", E9:E2880, "наличные") -> 140067.69 | D2: =B2+C2/0.76 -> 2384618.9 | F2: =SUMIFS(C9:C2880, B9:B2880, "оплачено", E9:E2880, "АльфаБанк")-SUMIFS(D9:D2880, B9:B2880, "оплачено", E9:E2880, "АльфаБанк")+14204002.07-7200 -> 2188332.6 | G2: =SUMIFS(C9:C2880, B9:B2880, "оплачено", E9:E2880, "ОПТ Банк")-SUMIFS(D9:D2880, B9:B2880, "оплачено", E9:E2880, "ОПТ Банк")-14204002.07+7200 -> 9951.98 | H2: =SUMIFS(C9:C2880, B9:B2880, "оплачено", E9:E2880, "Совкомбанк")-SUMIFS(D9:D2880, B9:B2880, "оплачено", E9:E2880, "Совкомбанк") -> 2034.74 | I2: 1716564.7 | J2: =J1*0.76 -> -358543.59 | K2: =C2-J2 -> 498611.28
A4: Прогноз | B4: Нам должны | C4: Мы должны | D4: Баланс прогнозный | M4: 1042062.6
B5: =SUMIF($B$9:$B$5935,"План поступлений",$C$9:$C$5935) -> 69238564 | C5: =SUMIF($B$9:$B$5935,"план оплат",$D$9:$D$5935) -> 60161516 | D5: =B5-C5+D2 -> 11461667 | J5: 3000000 | M5: =M4-905882.4 -> 136180.16
A8: Дата | B8: статус | C8: поступления | D8: списания | E8: Банк | F8: ПЕРИОД | G8: НДС | H8: НДС ФАКТ | I8: Статья | J8: Контрагент | K8: № дс | L8: Счет | M8: Счет от дата | N8: Просрочка дней | O8: Назначение
A9: 45132 | B9: ОПЛАЧЕНО | D9: 20970 | E9: АльфаБанк | F9: июль 2023 | G9: 0 | H9: =SUM(C9:D9)*G9/(G9+100) -> 0 | I9: IT | J9: ООО 1С-Битрикс | O9: Оплата по счет-заказу №5720598 от 25.07.2023 за права на программы для ЭВМ и сервисы. Без налога (НДС) НДС не облагается
A10: 45141 | B10: ОПЛАЧЕНО | D10: 1150 | E10: Наличные | F10: АВГУСТ 2023 | G10: 0 | H10: =SUM(C10:D10)*G10/(G10+100) -> 0 | I10: ПРОЧЕЕ | O10: доставка документов
A11: 45154 | B11: ОПЛАЧЕНО | D11: 1070 | E11: Наличные | F11: АВГУСТ 2023 | G11: 0 | H11: =SUM(C11:D11)*G11/(G11+100) -> 0 | I11: ПРОЧЕЕ | O11: доставка документов
A12: 45162 | B12: ОПЛАЧЕНО | C12: 93672 | E12: АльфаБанк | F12: АВГУСТ 2023 | G12: 20 | H12: =SUM(C12:D12)*G12/(G12+100) -> 15612 | I12: РЕАЛИЗАЦИЯ | J12: ООО РА СА МЕДИА | N12: =A12-IF(M12>0,M12,A12) -> 0 | O12: ОПЛАТА ПО СЧЕТУ №18 ОТ 24.07.2023 ЗА ПРОВЕДЕНИЕ РЕКЛАМНОЙ КАМПАНИИ В ИЮНЕ 23Г, ДОГОВОР №РМ-01-06-23 ОТ 01.06.2023, ДС 1 ОТ 01.06.23 СУММА 93672-00 В Т.Ч. НДС (20%) 15612-00
A13: 45167 | B13: ОПЛАЧЕНО | C13: 1404000 | E13: АльфаБанк | F13: АВГУСТ 2023 | G13: 20 | H13: =SUM(C13:D13)*G13/(G13+100) -> 234000 | I13: РЕАЛИЗАЦИЯ | J13: ООО СТРОНГ АДВЕРТАЙЗИНГ | N13: =A13-IF(M13>0,M13,A13) -> 0 | O13: ОПЛ. ПО СЧЕТУ № 22 ОТ 25.08.23 ЗА УСЛУГИ ПО РАЗМЕЩЕНИЮ РЕКЛАМНЫХ МАТЕРИАЛОВ (БРЕНД "ЭРКАФАРМ СЕВЕРО-ЗАПАД"/ "ОЗЕРКИ"). В Т.Ч. НДС 20 % - 234000.00 РУБ.
A14: 45170 | B14: ОПЛАЧЕНО | D14: 60000 | E14: Наличные | G14: 0 | H14: =SUM(C14:D14)*G14/(G14+100) -> 0 | I14: ПРОЧЕЕ | O14: фрилансер
A15: 45170 | B15: ОПЛАЧЕНО | D15: 28000 | E15: Наличные | G15: 0 | H15: =SUM(C15:D15)*G15/(G15+100) -> 0 | I15: ПРОЧЕЕ | O15: школа дайвинга
A16: 45173 | B16: ОПЛАЧЕНО | D16: 10 | E16: АльфаБанк | G16: 0 | H16: =SUM(C16:D16)*G16/(G16+100) -> 0 | I16: ОРД | J16: ООО ОРД-А | O16: Идентификационный платеж. НДС не облагается
A17: 45176 | B17: ОПЛАЧЕНО | D17: 875000 | E17: АльфаБанк | G17: 20 | H17: =SUM(C17:D17)*G17/(G17+100) -> 145833.33 | I17: ТРАНЗИТ | O17: транзит
A18: 45176 | B18: ОПЛАЧЕНО | C18: 630000 | E18: Наличные | F18: транзит | G18: 0 | H18: =SUM(C18:D18)*G18/(G18+100) -> 0 | I18: ТРАНЗИТ
A19: 45176 | B19: ОПЛАЧЕНО | D19: 630000 | E19: Наличные | G19: 0 | H19: =SUM(C19:D19)*G19/(G19+100) -> 0 | J19: ООО СТРОНГ АДВЕРТАЙЗИНГ | O19: стронг выдача
A20: 45198 | B20: ОПЛАЧЕНО | C20: 1176000 | E20: АльфаБанк | F20: реализация | G20: 20 | H20: =SUM(C20:D20)*G20/(G20+100) -> 196000 | I20: РЕАЛИЗАЦИЯ | J20: ООО СТРОНГ АДВЕРТАЙЗИНГ | N20: =A20-IF(M20>0,M20,A20) -> 0 | O20: Оплата по счету № 25 от 29.09.23 за услуги по размещению рекламных материалов (бренд "Эркафарм Северо-Запад"/ "Озерки"). В том числе НДС 20 % - 196000.00 рублей.
A21: 45203 | B21: ОПЛАЧЕНО | D21: 50750 | E21: Наличные | G21: 0 | H21: =SUM(C21:D21)*G21/(G21+100) -> 0 | I21: ПРЕМИЯ | J21: аккаунт | O21: 5335941005937933
A22: 45203 | B22: ОПЛАЧЕНО | D22: 17255 | E22: Наличные | G22: 0 | H22: =SUM(C22:D22)*G22/(G22+100) -> 0 | I22: ПРЕМИЯ | J22: физик | O22: отрисовка фигмы
A23: 45203 | B23: ОПЛАЧЕНО | C23: 56952 | E23: АльфаБанк | F23: реализация | G23: 20 | H23: =SUM(C23:D23)*G23/(G23+100) -> 9492 | I23: РЕАЛИЗАЦИЯ | N23: =A23-IF(M23>0,M23,A23) -> 0 | O23: ОПЛАТА ПО СЧЕТУ №19 ОТ 24.07.2023 ЗА ПРОВЕДЕНИЕ РЕКЛАМНОЙ КАМПАНИИ В ИЮЛЕ 23Г, ДОГОВОР №РМ-01-06-23 ОТ 01.06.2023, ДС 2 ОТ 01.07.23 СУММА 56952-00 В Т.Ч. НДС (20%) 9492-00
A24: 45203 | B24: ОПЛАЧЕНО | D24: 23730 | E24: АльфаБанк | G24: 20 | H24: =SUM(C24:D24)*G24/(G24+100) -> 3955 | I24: ПРОЧЕЕ | O24: По счету № 93 от 06 июля 2023 г. Услуги РИТ материалов в сети AdCamp в период 01.07.2023-06.07.2023 на основании Договора № ЭКР-2306236 от 23.06.2023 г В том числе НДС 20%, 3955.00 руб.
A25: 45203 | B25: ОПЛАЧЕНО | D25: 39030 | E25: АльфаБанк | G25: 20 | H25: =SUM(C25:D25)*G25/(G25+100) -> 6505 | I25: ПРОЧЕЕ | O25: По счету № 83 от 30 июня 2023 г Услуги РИМ в сети AdCamp в период 25.06.2023-30.06.2023 на основании Договора № ЭКР-2306236 от 23.06.2023 г. В том числе НДС 20%, 6505.00 руб.
A26: 45211 | B26: ОПЛАЧЕНО | D26: 722222 | E26: АльфаБанк | G26: 20 | H26: =SUM(C26:D26)*G26/(G26+100) -> 120370.33 | I26: ТРАНЗИТ | O26: транзит
A27: 45211 | B27: ОПЛАЧЕНО | C27: 519999.84 | E27: Наличные | F27: транзит | G27: 0 | H27: =SUM(C27:D27)*G27/(G27+100) -> 0 | I27: ТРАНЗИТ
A28: 45211 | B28: ОПЛАЧЕНО | D28: 520000 | E28: Наличные | G28: 0 | H28: =SUM(C28:D28)*G28/(G28+100) -> 0 | J28: ООО СТРОНГ АДВЕРТАЙЗИНГ | O28: стронг выдача
A29: 45216 | B29: ОПЛАЧЕНО | D29: 1090 | E29: Наличные | G29: 0 | H29: =SUM(C29:D29)*G29/(G29+100) -> 0 | O29: доставка документов
A30: 45217 | B30: ОПЛАЧЕНО | D30: 97996.24 | E30: АльфаБанк | G30: 0 | H30: =SUM(C30:D30)*G30/(G30+100) -> 0 | I30: ПОДРЯДЧИКИ | J30: ИП Лукин Евгений Витальевич | O30: По счету № 5 от 05 октября 2023 г. Услуги РИМ ОАО "МЮЗ" в сети Интернет по договору No 01/Р/В/23 от 01 сентября 2023 г. за период с 04.09.2023 г. по 30.09.2023 г. НДС не облагается
A31: 45217 | B31: ОПЛАЧЕНО | D31: 5000 | E31: АльфаБанк | G31: 20 | H31: =SUM(C31:D31)*G31/(G31+100) -> 833.33333 | I31: ОРД | J31: ООО ОРД-А | O31: По счету № 597 от 30.09.2023 Услуги по сбору, хранению, обработке и передаче Данных от Поставщика данных в ЕРИР посредством Системы ОРД-А , за сентябрь 2023 г. В том числе НДС 20%, 833.33 руб.
A32: 45217 | B32: ОПЛАЧЕНО | D32: 326388.89 | E32: АльфаБанк | G32: 20 | H32: =SUM(C32:D32)*G32/(G32+100) -> 54398.148 | I32: ТРАНЗИТ | O32: транзит
A33: 45217 | B33: ОПЛАЧЕНО | C33: 235000 | E33: Наличные | F33: транзит | G33: 0 | H33: =SUM(C33:D33)*G33/(G33+100) -> 0 | I33: ТРАНЗИТ
A34: 45217 | B34: ОПЛАЧЕНО | D34: 68729.86 | E34: АльфаБанк | G34: 20 | H34: =SUM(C34:D34)*G34/(G34+100) -> 11454.977 | I34: БОНУСЫ | J34: ООО ПМ | O34: 0.02
A35: 45217 | B35: ОПЛАЧЕНО | D35: 5000 | E35: АльфаБанк | G35: 20 | H35: =SUM(C35:D35)*G35/(G35+100) -> 833.33333 | I35: ОРД | J35: ООО ОРД-А | O35: По счету № 597 от 30.09.2023 Услуги по сбору, хранению, обработке и передаче Данных от Поставщика данных в ЕРИР посредством Системы ОРД-А , за сентябрь 2023 г. В том числе НДС 20%, 833.33 руб.
A36: 45218 | B36: ОПЛАЧЕНО | D36: 23500 | E36: Наличные | G36: 0 | H36: =SUM(C36:D36)*G36/(G36+100) -> 0 | O36: 4377723766690287 Роман Ц.
A37: 45222 | B37: ОПЛАЧЕНО | D37: 50750 | E37: Наличные | G37: 0 | H37: =SUM(C37:D37)*G37/(G37+100) -> 0 | I37: ФОТ | J37: ФОТ | O37: ЗП аккаунту - 5335941005937933
A38: 45223 | B38: ОПЛАЧЕНО | C38: 345869.1 | E38: АльфаБанк | F38: реализация | G38: 20 | H38: =SUM(C38:D38)*G38/(G38+100) -> 57644.85 | I38: РЕАЛИЗАЦИЯ | J38: ООО РА СА МЕДИА | N38: =A38-IF(M38>0,M38,A38) -> 0 | O38: Оплата по счету №30 от 09.10.2023 за услуги по размещению РИМ в сентябре 23г, договор №РМ-01-06-23 от 01.06.2023, ДС 4 от 30.08.23 Сумма 345869-10 В т.ч. НДС (20%) 57644-85
A39: 45231 | B39: ОПЛАЧЕНО | D39: 265229.19 | E39: АльфаБанк | G39: 0 | H39: =SUM(C39:D39)*G39/(G39+100) -> 0 | I39: НАЛОГИ | J39: МИ ФНС РОССИИ ПО УПРАВЛЕНИЮ ДОЛГОМ
A40: 45231 | B40: ОПЛАЧЕНО | D40: 212183.36 | E40: АльфаБанк | G40: 0 | H40: =SUM(C40:D40)*G40/(G40+100) -> 0 | I40: НАЛОГИ | J40: МИ ФНС РОССИИ ПО УПРАВЛЕНИЮ ДОЛГОМ
A41: 45233 | B41: ОПЛАЧЕНО | D41: 23561 | E41: Наличные | G41: 0 | H41: =SUM(C41:D41)*G41/(G41+100) -> 0 | I41: ПРОЧЕЕ | O41: 2200 7001 3648 8748
A42: 45237 | B42: ОПЛАЧЕНО | D42: 24000 | E42: Наличные | G42: 0 | H42: =SUM(C42:D42)*G42/(G42+100) -> 0 | I42: ПРОЧЕЕ | O42: 7 952 773 3683 - тинек, Роман
A43: 45240 | B43: ОПЛАЧЕНО | C43: 846913.92 | E43: АльфаБанк | F43: реализация | G43: 20 | H43: =SUM(C43:D43)*G43/(G43+100) -> 141152.32 | I43: РЕАЛИЗАЦИЯ | J43: ООО ДИДЖИТАЛЬНЫЕ ТЕХНОЛОГИИ | N43: =A43-IF(M43>0,M43,A43) -> 0 | O43: Оплата по сч 34 от 09.11.2023 за Услуги по аналитич. обзору рек. рынка на территории Узбекистан в нояб 2023 г, согл ДС 2 от 1.11.23 к дог PM-13-07-23 от 13.07.23 Сумма 846913-92 В т.ч. НДС (20%) 141152-32
...

Sheet БДДС 2026
B1: РЕАЛИЗАЦИЯ | C1: =SUM(J1+R1+Z1+AH1) -> 76426216 | D1: =SUM(D7:D41) -> 4788498.2 | F1: =SUM(F7:F41) -> 21363945 | H1: =SUM(H7:H41) -> 29861476 | J1: =SUM(J7:J41) -> 56013919 | L1: =SUM(L7:L41) -> 17354785 | N1: =SUM(N7:N41) -> 57500 | P1: =SUM(P7:P41) -> 3000000 | R1: =SUM(R7:R41) -> 20412285 | T1: =SUM(T7:T41) -> 0 | V1: =SUM(V7:V41) -> 0 | X1: =SUM(X7:X41) -> 0 | Z1: =SUM(Z7:Z41) -> 0 | AB1: =SUM(AB7:AB41) -> 12 | AD1: =SUM(AD7:AD41) -> 0 | AF1: =SUM(AF7:AF41) -> 0 | AH1: =SUM(AH7:AH41) -> 12
B2: РАСХОДЫ | C2: =SUM(J2+R2+Z2+AH2) -> 79668913 | D2: =SUM(E7:E41)-E15-E22 -> 8075496.9 | F2: =SUM(G7:G41)-G15-G22 -> 12308661 | H2: =SUM(I7:I41)-I15-I22 -> 21283997 | J2: =SUM(K7:K41)-K15-K22 -> 54994398 | L2: =SUM(M7:M41)-M15-M22 -> 14948734 | N2: =SUM(O7:O41)-O15-O22 -> 8734780.9 | P2: =SUM(Q7:Q41)-Q15-Q22 -> 885067.52 | R2: =SUM(S7:S41)-S15-S22 -> 24674515 | T2: =SUM(U7:U41)-U15-U22 -> 0 | V2: =SUM(W7:W41)-W15-W22 -> 0 | X2: =SUM(Y7:Y41)-Y15-Y22 -> 0 | Z2: =SUM(AA7:AA41)-AA15-AA22 -> 0 | AB2: =SUM(AC7:AC41)-AC15-AC22 -> 0 | AD2: =SUM(AE7:AE41)-AE15-AE22 -> 0 | AF2: =SUM(AG7:AG41)-AG15-AG22 -> 0 | AH2: =SUM(AI7:AI41)-AI15-AI22 -> 0
B3: Дельта | C3: =SUM(J3+R3+Z3+AH3) -> -3242696.9 | D3: =D1-D2 -> -3286998.8 | F3: =F1-F2 -> 9055283.9 | H3: =H1-H2 -> 8577479.1 | J3: =J1-J2 -> 1019520.3 | L3: =L1-L2 -> 2406051.2 | N3: =N1-N2 -> -8677280.9 | P3: =P1-P2 -> 2114932.5 | R3: =R1-R2 -> -4262229.3 | T3: =T1-T2 -> 0 | V3: =V1-V2 -> 0 | X3: =X1-X2 -> 0 | Z3: =Z1-Z2 -> 0 | AB3: =AB1-AB2 -> 12 | AD3: =AD1-AD2 -> 0 | AF3: =AF1-AF2 -> 0 | AH3: =AH1-AH2 -> 12
C5: 2026 год | E5: ЯНВАРЬ 2026 | G5: ФЕВРАЛЬ 2026 | I5: МАРТ 2026 | K5: 1 квартал 2026 | M5: АПРЕЛЬ 2026 | O5: МАЙ 2026 | Q5: ИЮНЬ 2026 | S5: 2 квартал 2026 | U5: ИЮЛЬ 2026 | W5: АВГУСТ 2026 | Y5: СЕНТЯБРЬ 2026 | AA5: 3 квартал 2026 | AC5: Октябрь 2026 | AE5: НОЯБРЬ 2026 | AG5: ДЕКАБРЬ 2026 | AI5: 4 квартал 2026
D6: поступления | E6: расходы | F6: поступления | G6: расходы | H6: поступления | I6: расходы | J6: поступления | K6: расходы | L6: поступления | M6: расходы | N6: поступления | O6: расходы | P6: поступления | Q6: расходы | R6: поступления | S6: расходы | T6: поступления | U6: расходы | V6: поступления | W6: расходы | X6: поступления | Y6: расходы | Z6: поступления | AA6: расходы | AB6: поступления | AC6: расходы | AD6: поступления | AE6: расходы | AF6: поступления | AG6: расходы | AH6: поступления | AI6: расходы
B7: РЕАЛИЗАЦИЯ | C7: =J7+R7+Z7+AH7 -> 71982438 | D7: =SUMIFS('CF BEST'!$C$9:$C1013, 'CF BEST'!$I$9:$I1013, B7,'CF BEST'!$F$9:$F1013, $E$5) -> 4788498.2 | E7: =SUMIFS('CF BEST'!$D$9:$D1013, 'CF BEST'!$I$9:$I1013, B7,'CF BEST'!$F$9:$F1013, $E$5) -> 0 | F7: =SUMIFS('CF BEST'!$C$9:$C1013, 'CF BEST'!$I$9:$I1013, B7,'CF BEST'!$F$9:$F1013, $G$5) -> 21363945 | G7: =SUMIFS('CF BEST'!$D$9:$D1013, 'CF BEST'!$I$9:$I1013, B7,'CF BEST'!$F$9:$F1013, $G$5) -> 0 | H7: =SUMIFS('CF BEST'!$C$9:$C1013, 'CF BEST'!$I$9:$I1013, B7,'CF BEST'!$F$9:$F1013, $I$5) -> 28475210 | I7: =SUMIFS('CF BEST'!$D$9:$D1013, 'CF BEST'!$I$9:$I1013, B7,'CF BEST'!$F$9:$F1013, $I$5) -> 0 | J7: =SUMIFS('CF BEST'!$C$9:$C1013, 'CF BEST'!$I$9:$I1013, B7,'CF BEST'!$F$9:$F1013, $K$5)+D7+F7+H7 -> 54627653 | K7: =SUMIFS('CF BEST'!$D$9:$D1013, 'CF BEST'!$I$9:$I1013, B7,'CF BEST'!$F$9:$F1013, $K$5)+E7+G7+I7 -> 0 | L7: =SUMIFS('CF BEST'!$C$9:$C1013, 'CF BEST'!$I$9:$I1013, B7,'CF BEST'!$F$9:$F1013, $M$5) -> 17354785 | M7: =SUMIFS('CF BEST'!$D$9:$D1013, 'CF BEST'!$I$9:$I1013, B7,'CF BEST'!$F$9:$F1013, $M$5) -> 0 | N7: =SUMIFS('CF BEST'!$C$9:$C1013, 'CF BEST'!$I$9:$I1013, B7,'CF BEST'!$F$9:$F1013, $O$5) -> 0 | O7: =SUMIFS('CF BEST'!$D$9:$D1013, 'CF BEST'!$I$9:$I1013, B7,'CF BEST'!$F$9:$F1013, $O$5) -> 0 | P7: =SUMIFS('CF BEST'!$C$9:$C1013, 'CF BEST'!$I$9:$I1013, B7,'CF BEST'!$F$9:$F1013, $Q$5) -> 0 | Q7: =SUMIFS('CF BEST'!$D$9:$D1013, 'CF BEST'!$I$9:$I1013, B7,'CF BEST'!$F$9:$F1013, $Q$5) -> 0 | R7: =SUMIFS('CF BEST'!$C$9:$C1013, 'CF BEST'!$I$9:$I1013, B7,'CF BEST'!$F$9:$F1013, $S$5)+L7+N7+P7 -> 17354785 | S7: =SUMIFS('CF BEST'!$D$9:$D1013, 'CF BEST'!$I$9:$I1013, B7,'CF BEST'!$F$9:$F1013, $S$5)+M7+O7+Q7 -> 0 | T7: =SUMIFS('CF BEST'!$C$9:$C1013, 'CF BEST'!$I$9:$I1013, B7,'CF BEST'!$F$9:$F1013, $U$5) -> 0 | U7: =SUMIFS('CF BEST'!$D$9:$D1013, 'CF BEST'!$I$9:$I1013, B7,'CF BEST'!$F$9:$F1013, $U$5) -> 0 | V7: =SUMIFS('CF BEST'!$C$9:$C1013, 'CF BEST'!$I$9:$I1013, B7,'CF BEST'!$F$9:$F1013, $W$5) -> 0 | W7: =SUMIFS('CF BEST'!$D$9:$D1013, 'CF BEST'!$I$9:$I1013, B7,'CF BEST'!$F$9:$F1013, $W$5) -> 0 | X7: =SUMIFS('CF BEST'!$C$9:$C1013, 'CF BEST'!$I$9:$I1013, B7,'CF BEST'!$F$9:$F1013, $Y$5) -> 0 | Y7: =SUMIFS('CF BEST'!$D$9:$D1013, 'CF BEST'!$I$9:$I1013, B7,'CF BEST'!$F$9:$F1013, $Y$5) -> 0 | Z7: =SUMIFS('CF BEST'!$C$9:$C1013, 'CF BEST'!$I$9:$I1013, B7,'CF BEST'!$F$9:$F1013, $AA$5)+T7+V7+X7 -> 0 | AA7: =SUMIFS('CF BEST'!$D$9:$D1013, 'CF BEST'!$I$9:$I1013, B7,'CF BEST'!$F$9:$F1013, $AA$5)+U7+W7+Y7 -> 0 | AB7: =SUMIFS('CF BEST'!$C$9:$C1013, 'CF BEST'!$I$9:$I1013, B7,'CF BEST'!$F$9:$F1013, $AC$5) -> 0 | AC7: =SUMIFS('CF BEST'!$D$9:$D1013, 'CF BEST'!$I$9:$I1013, B7,'CF BEST'!$F$9:$F1013, $AC$5) -> 0 | AD7: =SUMIFS('CF BEST'!$C$9:$C1013, 'CF BEST'!$I$9:$I1013, B7,'CF BEST'!$F$9:$F1013, $AE$5) -> 0 | AE7: =SUMIFS('CF BEST'!$D$9:$D1013, 'CF BEST'!$I$9:$I1013, B7,'CF BEST'!$F$9:$F1013, $AE$5) -> 0 | AF7: =SUMIFS('CF BEST'!$C$9:$C1013, 'CF BEST'!$I$9:$I1013, B7,'CF BEST'!$F$9:$F1013, $AG$5) -> 0 | AG7: =SUMIFS('CF BEST'!$D$9:$D1013, 'CF BEST'!$I$9:$I1013, B7,'CF BEST'!$F$9:$F1013, $AG$5) -> 0 | AH7: =SUMIFS('CF BEST'!$C$9:$C1013, 'CF BEST'!$I$9:$I1013, B7,'CF BEST'!$F$9:$F1013, $AI$5)+AB7+AD7+AF7 -> 0 | AI7: =SUMIFS('CF BEST'!$D$9:$D1013, 'CF BEST'!$I$9:$I1013, B7,'CF BEST'!$F$9:$F1013, $AI$5)+AC7+AE7+AG7 -> 0
A8: =C8/$C$7 -> 0.17799914 | B8: СК АГЕНТСКАЯ | C8: =K8+S8+AA8+AI8 -> 12812812 | D8: =SUMIFS('CF BEST'!$C$9:$C1013, 'CF BEST'!$I$9:$I1013, B8,'CF BEST'!$F$9:$F1013, $E$5) -> 0 | E8: =SUMIFS('CF BEST'!$D$9:$D1013, 'CF BEST'!$I$9:$I1013, B8,'CF BEST'!$F$9:$F1013, $E$5) -> 0 | F8: =SUMIFS('CF BEST'!$C$9:$C1013, 'CF BEST'!$I$9:$I1013, B8,'CF BEST'!$F$9:$F1013, $G$5) -> 0 | G8: =SUMIFS('CF BEST'!$D$9:$D1013, 'CF BEST'!$I$9:$I1013, B8,'CF BEST'!$F$9:$F1013, $G$5) -> 0 | H8: =SUMIFS('CF BEST'!$C$9:$C1013, 'CF BEST'!$I$9:$I1013, B8,'CF BEST'!$F$9:$F1013, $I$5) -> 0 | I8: =SUMIFS('CF BEST'!$D$9:$D1013, 'CF BEST'!$I$9:$I1013, B8,'CF BEST'!$F$9:$F1013, $I$5) -> 0 | J8: =SUMIFS('CF BEST'!$C$9:$C1013, 'CF BEST'!$I$9:$I1013, B8,'CF BEST'!$F$9:$F1013, $K$5)+D8+F8+H8 -> 0 | K8: =SUMIFS('CF BEST'!$D$9:$D1013, 'CF BEST'!$I$9:$I1013, B8,'CF BEST'!$F$9:$F1013, $K$5)+E8+G8+I8 -> 8208812.3 | L8: =SUMIFS('CF BEST'!$C$9:$C1013, 'CF BEST'!$I$9:$I1013, B8,'CF BEST'!$F$9:$F1013, $M$5) -> 0 | M8: =SUMIFS('CF BEST'!$D$9:$D1013, 'CF BEST'!$I$9:$I1013, B8,'CF BEST'!$F$9:$F1013, $M$5) -> 4604000 | N8: =SUMIFS('CF BEST'!$C$9:$C1013, 'CF BEST'!$I$9:$I1013, B8,'CF BEST'!$F$9:$F1013, $O$5) -> 0 | O8: =SUMIFS('CF BEST'!$D$9:$D1013, 'CF BEST'!$I$9:$I1013, B8,'CF BEST'!$F$9:$F1013, $O$5) -> 0 | P8: =SUMIFS('CF BEST'!$C$9:$C1013, 'CF BEST'!$I$9:$I1013, B8,'CF BEST'!$F$9:$F1013, $Q$5) -> 0 | Q8: =SUMIFS('CF BEST'!$D$9:$D1013, 'CF BEST'!$I$9:$I1013, B8,'CF BEST'!$F$9:$F1013, $Q$5) -> 0 | R8: =SUMIFS('CF BEST'!$C$9:$C1013, 'CF BEST'!$I$9:$I1013, B8,'CF BEST'!$F$9:$F1013, $S$5)+L8+N8+P8 -> 0 | S8: =SUMIFS('CF BEST'!$D$9:$D1013, 'CF BEST'!$I$9:$I1013, B8,'CF BEST'!$F$9:$F1013, $S$5)+M8+O8+Q8 -> 4604000 | T8: =SUMIFS('CF BEST'!$C$9:$C1013, 'CF BEST'!$I$9:$I1013, B8,'CF BEST'!$F$9:$F1013, $U$5) -> 0 | U8: =SUMIFS('CF BEST'!$D$9:$D1013, 'CF BEST'!$I$9:$I1013, B8,'CF BEST'!$F$9:$F1013, $U$5) -> 0 | V8: =SUMIFS('CF BEST'!$C$9:$C1013, 'CF BEST'!$I$9:$I1013, B8,'CF BEST'!$F$9:$F1013, $W$5) -> 0 | W8: =SUMIFS('CF BEST'!$D$9:$D1013, 'CF BEST'!$I$9:$I1013, B8,'CF BEST'!$F$9:$F1013, $W$5) -> 0 | X8: =SUMIFS('CF BEST'!$C$9:$C1013, 'CF BEST'!$I$9:$I1013, B8,'CF BEST'!$F$9:$F1013, $Y$5) -> 0 | Y8: =SUMIFS('CF BEST'!$D$9:$D1013, 'CF BEST'!$I$9:$I1013, B8,'CF BEST'!$F$9:$F1013, $Y$5) -> 0 | Z8: =SUMIFS('CF BEST'!$C$9:$C1013, 'CF BEST'!$I$9:$I1013, B8,'CF BEST'!$F$9:$F1013, $AA$5)+T8+V8+X8 -> 0 | AA8: =SUMIFS('CF BEST'!$D$9:$D1013, 'CF BEST'!$I$9:$I1013, B8,'CF BEST'!$F$9:$F1013, $AA$5)+U8+W8+Y8 -> 0 | AB8: =SUMIFS('CF BEST'!$C$9:$C1013, 'CF BEST'!$I$9:$I1013, B8,'CF BEST'!$F$9:$F1013, $AC$5) -> 0 | AC8: =SUMIFS('CF BEST'!$D$9:$D1013, 'CF BEST'!$I$9:$I1013, B8,'CF BEST'!$F$9:$F1013, $AC$5) -> 0 | AD8: =SUMIFS('CF BEST'!$C$9:$C1013, 'CF BEST'!$I$9:$I1013, B8,'CF BEST'!$F$9:$F1013, $AE$5) -> 0 | AE8: =SUMIFS('CF BEST'!$D$9:$D1013, 'CF BEST'!$I$9:$I1013, B8,'CF BEST'!$F$9:$F1013, $AE$5) -> 0 | AF8: =SUMIFS('CF BEST'!$C$9:$C1013, 'CF BEST'!$I$9:$I1013, B8,'CF BEST'!$F$9:$F1013, $AG$5) -> 0 | AG8: =SUMIFS('CF BEST'!$D$9:$D1013, 'CF BEST'!$I$9:$I1013, B8,'CF BEST'!$F$9:$F1013, $AG$5) -> 0 | AH8: =SUMIFS('CF BEST'!$C$9:$C1013, 'CF BEST'!$I$9:$I1013, B8,'CF BEST'!$F$9:$F1013, $AI$5)+AB8+AD8+AF8 -> 0 | AI8: =SUMIFS('CF BEST'!$D$9:$D1013, 'CF BEST'!$I$9:$I1013, B8,'CF BEST'!$F$9:$F1013, $AI$5)+AC8+AE8+AG8 -> 0
A9: =C9/$C$7 -> 0.0038203763 | B9: СК ПАРТНЕРСКАЯ | C9: =K9+S9+AA9+AI9 -> 275000 | D9: =SUMIFS('CF BEST'!$C$9:$C1013, 'CF BEST'!$I$9:$I1013, B9,'CF BEST'!$F$9:$F1013, $E$5) -> 0 | E9: =SUMIFS('CF BEST'!$D$9:$D1013, 'CF BEST'!$I$9:$I1013, B9,'CF BEST'!$F$9:$F1013, $E$5) -> 0 | F9: =SUMIFS('CF BEST'!$C$9:$C1013, 'CF BEST'!$I$9:$I1013, B9,'CF BEST'!$F$9:$F1013, $G$5) -> 0 | G9: =SUMIFS('CF BEST'!$D$9:$D1013, 'CF BEST'!$I$9:$I1013, B9,'CF BEST'!$F$9:$F1013, $G$5) -> 0 | H9: =SUMIFS('CF BEST'!$C$9:$C1013, 'CF BEST'!$I$9:$I1013, B9,'CF BEST'!$F$9:$F1013, $I$5) -> 0 | I9: =SUMIFS('CF BEST'!$D$9:$D1013, 'CF BEST'!$I$9:$I1013, B9,'CF BEST'!$F$9:$F1013, $I$5) -> 0 | J9: =SUMIFS('CF BEST'!$C$9:$C1013, 'CF BEST'!$I$9:$I1013, B9,'CF BEST'!$F$9:$F1013, $K$5)+D9+F9+H9 -> 0 | K9: =SUMIFS('CF BEST'!$D$9:$D1013, 'CF BEST'!$I$9:$I1013, B9,'CF BEST'!$F$9:$F1013, $K$5)+E9+G9+I9 -> 275000 | L9: =SUMIFS('CF BEST'!$C$9:$C1013, 'CF BEST'!$I$9:$I1013, B9,'CF BEST'!$F$9:$F1013, $M$5) -> 0 | M9: =SUMIFS('CF BEST'!$D$9:$D1013, 'CF BEST'!$I$9:$I1013, B9,'CF BEST'!$F$9:$F1013, $M$5) -> 0 | N9: =SUMIFS('CF BEST'!$C$9:$C1013, 'CF BEST'!$I$9:$I1013, B9,'CF BEST'!$F$9:$F1013, $O$5) -> 0 | O9: =SUMIFS('CF BEST'!$D$9:$D1013, 'CF BEST'!$I$9:$I1013, B9,'CF BEST'!$F$9:$F1013, $O$5) -> 0 | P9: =SUMIFS('CF BEST'!$C$9:$C1013, 'CF BEST'!$I$9:$I1013, B9,'CF BEST'!$F$9:$F1013, $Q$5) -> 0 | Q9: =SUMIFS('CF BEST'!$D$9:$D1013, 'CF BEST'!$I$9:$I1013, B9,'CF BEST'!$F$9:$F1013, $Q$5) -> 0 | R9: =SUMIFS('CF BEST'!$C$9:$C1013, 'CF BEST'!$I$9:$I1013, B9,'CF BEST'!$F$9:$F1013, $S$5)+L9+N9+P9 -> 0 | S9: =SUMIFS('CF BEST'!$D$9:$D1013, 'CF BEST'!$I$9:$I1013, B9,'CF BEST'!$F$9:$F1013, $S$5)+M9+O9+Q9 -> 0 | T9: =SUMIFS('CF BEST'!$C$9:$C1013, 'CF BEST'!$I$9:$I1013, B9,'CF BEST'!$F$9:$F1013, $U$5) -> 0 | U9: =SUMIFS('CF BEST'!$D$9:$D1013, 'CF BEST'!$I$9:$I1013, B9,'CF BEST'!$F$9:$F1013, $U$5) -> 0 | V9: =SUMIFS('CF BEST'!$C$9:$C1013, 'CF BEST'!$I$9:$I1013, B9,'CF BEST'!$F$9:$F1013, $W$5) -> 0 | W9: =SUMIFS('CF BEST'!$D$9:$D1013, 'CF BEST'!$I$9:$I1013, B9,'CF BEST'!$F$9:$F1013, $W$5) -> 0 | X9: =SUMIFS('CF BEST'!$C$9:$C1013, 'CF BEST'!$I$9:$I1013, B9,'CF BEST'!$F$9:$F1013, $Y$5) -> 0 | Y9: =SUMIFS('CF BEST'!$D$9:$D1013, 'CF BEST'!$I$9:$I1013, B9,'CF BEST'!$F$9:$F1013, $Y$5) -> 0 | Z9: =SUMIFS('CF BEST'!$C$9:$C1013, 'CF BEST'!$I$9:$I1013, B9,'CF BEST'!$F$9:$F1013, $AA$5)+T9+V9+X9 -> 0 | AA9: =SUMIFS('CF BEST'!$D$9:$D1013, 'CF BEST'!$I$9:$I1013, B9,'CF BEST'!$F$9:$F1013, $AA$5)+U9+W9+Y9 -> 0 | AB9: =SUMIFS('CF BEST'!$C$9:$C1013, 'CF BEST'!$I$9:$I1013, B9,'CF BEST'!$F$9:$F1013, $AC$5) -> 0 | AC9: =SUMIFS('CF BEST'!$D$9:$D1013, 'CF BEST'!$I$9:$I1013, B9,'CF BEST'!$F$9:$F1013, $AC$5) -> 0 | AD9: =SUMIFS('CF BEST'!$C$9:$C1013, 'CF BEST'!$I$9:$I1013, B9,'CF BEST'!$F$9:$F1013, $AE$5) -> 0 | AE9: =SUMIFS('CF BEST'!$D$9:$D1013, 'CF BEST'!$I$9:$I1013, B9,'CF BEST'!$F$9:$F1013, $AE$5) -> 0 | AF9: =SUMIFS('CF BEST'!$C$9:$C1013, 'CF BEST'!$I$9:$I1013, B9,'CF BEST'!$F$9:$F1013, $AG$5) -> 0 | AG9: =SUMIFS('CF BEST'!$D$9:$D1013, 'CF BEST'!$I$9:$I1013, B9,'CF BEST'!$F$9:$F1013, $AG$5) -> 0 | AH9: =SUMIFS('CF BEST'!$C$9:$C1013, 'CF BEST'!$I$9:$I1013, B9,'CF BEST'!$F$9:$F1013, $AI$5)+AB9+AD9+AF9 -> 0 | AI9: =SUMIFS('CF BEST'!$D$9:$D1013, 'CF BEST'!$I$9:$I1013, B9,'CF BEST'!$F$9:$F1013, $AI$5)+AC9+AE9+AG9 -> 0
A10: =C10/$C$7 -> 0.20966114 | B10: АПТЕКА | C10: =K10+S10+AA10+AI10 -> 15091920 | D10: =SUMIFS('CF BEST'!$C$9:$C1013, 'CF BEST'!$I$9:$I1013, B10,'CF BEST'!$F$9:$F1013, $E$5) -> 0 | E10: =SUMIFS('CF BEST'!$D$9:$D1013, 'CF BEST'!$I$9:$I1013, B10,'CF BEST'!$F$9:$F1013, $E$5) -> 1530063.2 | F10: =SUMIFS('CF BEST'!$C$9:$C1013, 'CF BEST'!$I$9:$I1013, B10,'CF BEST'!$F$9:$F1013, $G$5) -> 0 | G10: =SUMIFS('CF BEST'!$D$9:$D1013, 'CF BEST'!$I$9:$I1013, B10,'CF BEST'!$F$9:$F1013, $G$5) -> 3151697.2 | H10: =SUMIFS('CF BEST'!$C$9:$C1013, 'CF BEST'!$I$9:$I1013, B10,'CF BEST'!$F$9:$F1013, $I$5) -> 0 | I10: =SUMIFS('CF BEST'!$D$9:$D1013, 'CF BEST'!$I$9:$I1013, B10,'CF BEST'!$F$9:$F1013, $I$5) -> 6225997.1 | J10: =SUMIFS('CF BEST'!$C$9:$C1013, 'CF BEST'!$I$9:$I1013, B10,'CF BEST'!$F$9:$F1013, $K$5)+D10+F10+H10 -> 0 | K10: =SUMIFS('CF BEST'!$D$9:$D1013, 'CF BEST'!$I$9:$I1013, B10,'CF BEST'!$F$9:$F1013, $K$5)+E10+G10+I10 -> 10907758 | L10: =SUMIFS('CF BEST'!$C$9:$C1013, 'CF BEST'!$I$9:$I1013, B10,'CF BEST'!$F$9:$F1013, $M$5) -> 0 | M10: =SUMIFS('CF BEST'!$D$9:$D1013, 'CF BEST'!$I$9:$I1013, B10,'CF BEST'!$F$9:$F1013, $M$5) -> 2755386.2 | N10: =SUMIFS('CF BEST'!$C$9:$C1013, 'CF BEST'!$I$9:$I1013, B10,'CF BEST'!$F$9:$F1013, $O$5) -> 0 | O10: =SUMIFS('CF BEST'!$D$9:$D1013, 'CF BEST'!$I$9:$I1013, B10,'CF BEST'!$F$9:$F1013, $O$5) -> 1278776.6 | P10: =SUMIFS('CF BEST'!$C$9:$C1013, 'CF BEST'!$I$9:$I1013, B10,'CF BEST'!$F$9:$F1013, $Q$5) -> 0 | Q10: =SUMIFS('CF BEST'!$D$9:$D1013, 'CF BEST'!$I$9:$I1013, B10,'CF BEST'!$F$9:$F1013, $Q$5) -> 150000 | R10: =SUMIFS('CF BEST'!$C$9:$C1013, 'CF BEST'!$I$9:$I1013, B10,'CF BEST'!$F$9:$F1013, $S$5)+L10+N10+P10 -> 0 | S10: =SUMIFS('CF BEST'!$D$9:$D1013, 'CF BEST'!$I$9:$I1013, B10,'CF BEST'!$F$9:$F1013, $S$5)+M10+O10+Q10 -> 4184162.8 | T10: =SUMIFS('CF BEST'!$C$9:$C1013, 'CF BEST'!$I$9:$I1013, B10,'CF BEST'!$F$9:$F1013, $U$5) -> 0 | U10: =SUMIFS('CF BEST'!$D$9:$D1013, 'CF BEST'!$I$9:$I1013, B10,'CF BEST'!$F$9:$F1013, $U$5) -> 0 | V10: =SUMIFS('CF BEST'!$C$9:$C1013, 'CF BEST'!$I$9:$I1013, B10,'CF BEST'!$F$9:$F1013, $W$5) -> 0 | W10: =SUMIFS('CF BEST'!$D$9:$D1013, 'CF BEST'!$I$9:$I1013, B10,'CF BEST'!$F$9:$F1013, $W$5) -> 0 | X10: =SUMIFS('CF BEST'!$C$9:$C1013, 'CF BEST'!$I$9:$I1013, B10,'CF BEST'!$F$9:$F1013, $Y$5) -> 0 | Y10: =SUMIFS('CF BEST'!$D$9:$D1013, 'CF BEST'!$I$9:$I1013, B10,'CF BEST'!$F$9:$F1013, $Y$5) -> 0 | Z10: =SUMIFS('CF BEST'!$C$9:$C1013, 'CF BEST'!$I$9:$I1013, B10,'CF BEST'!$F$9:$F1013, $AA$5)+T10+V10+X10 -> 0 | AA10: =SUMIFS('CF BEST'!$D$9:$D1013, 'CF BEST'!$I$9:$I1013, B10,'CF BEST'!$F$9:$F1013, $AA$5)+U10+W10+Y10 -> 0 | AB10: =SUMIFS('CF BEST'!$C$9:$C1013, 'CF BEST'!$I$9:$I1013, B10,'CF BEST'!$F$9:$F1013, $AC$5) -> 0 | AC10: =SUMIFS('CF BEST'!$D$9:$D1013, 'CF BEST'!$I$9:$I1013, B10,'CF BEST'!$F$9:$F1013, $AC$5) -> 0 | AD10: =SUMIFS('CF BEST'!$C$9:$C1013, 'CF BEST'!$I$9:$I1013, B10,'CF BEST'!$F$9:$F1013, $AE$5) -> 0 | AE10: =SUMIFS('CF BEST'!$D$9:$D1013, 'CF BEST'!$I$9:$I1013, B10,'CF BEST'!$F$9:$F1013, $AE$5) -> 0 | AF10: =SUMIFS('CF BEST'!$C$9:$C1013, 'CF BEST'!$I$9:$I1013, B10,'CF BEST'!$F$9:$F1013, $AG$5) -> 0 | AG10: =SUMIFS('CF BEST'!$D$9:$D1013, 'CF BEST'!$I$9:$I1013, B10,'CF BEST'!$F$9:$F1013, $AG$5) -> 0 | AH10: =SUMIFS('CF BEST'!$C$9:$C1013, 'CF BEST'!$I$9:$I1013, B10,'CF BEST'!$F$9:$F1013, $AI$5)+AB10+AD10+AF10 -> 0 | AI10: =SUMIFS('CF BEST'!$D$9:$D1013, 'CF BEST'!$I$9:$I1013, B10,'CF BEST'!$F$9:$F1013, $AI$5)+AC10+AE10+AG10 -> 0
A11: =C11/$C$7 -> 0.072564764 | B11: ПАБЛИШЕР | C11: =K11+S11+AA11+AI11 -> 5223388.6 | D11: =SUMIFS('CF BEST'!$C$9:$C1013, 'CF BEST'!$I$9:$I1013, B11,'CF BEST'!$F$9:$F1013, $E$5) -> 0 | E11: =SUMIFS('CF BEST'!$D$9:$D1013, 'CF BEST'!$I$9:$I1013, B11,'CF BEST'!$F$9:$F1013, $E$5) -> 390512.39 | F11: =SUMIFS('CF BEST'!$C$9:$C1013, 'CF BEST'!$I$9:$I1013, B11,'CF BEST'!$F$9:$F1013, $G$5) -> 0 | G11: =SUMIFS('CF BEST'!$D$9:$D1013, 'CF BEST'!$I$9:$I1013, B11,'CF BEST'!$F$9:$F1013, $G$5) -> 2241357.2 | H11: =SUMIFS('CF BEST'!$C$9:$C1013, 'CF BEST'!$I$9:$I1013, B11,'CF BEST'!$F$9:$F1013, $I$5) -> 0 | I11: =SUMIFS('CF BEST'!$D$9:$D1013, 'CF BEST'!$I$9:$I1013, B11,'CF BEST'!$F$9:$F1013, $I$5) -> 2150444 | J11: =SUMIFS('CF BEST'!$C$9:$C1013, 'CF BEST'!$I$9:$I1013, B11,'CF BEST'!$F$9:$F1013, $K$5)+D11+F11+H11 -> 0 | K11: =SUMIFS('CF BEST'!$D$9:$D1013, 'CF BEST'!$I$9:$I1013, B11,'CF BEST'!$F$9:$F1013, $K$5)+E11+G11+I11 -> 4782313.5 | L11: =SUMIFS('CF BEST'!$C$9:$C1013, 'CF BEST'!$I$9:$I1013, B11,'CF BEST'!$F$9:$F1013, $M$5) -> 0 | M11: =SUMIFS('CF BEST'!$D$9:$D1013, 'CF BEST'!$I$9:$I1013, B11,'CF BEST'!$F$9:$F1013, $M$5) -> 441075.07 | N11: =SUMIFS('CF BEST'!$C$9:$C1013, 'CF BEST'!$I$9:$I1013, B11,'CF BEST'!$F$9:$F1013, $O$5) -> 0 | O11: =SUMIFS('CF BEST'!$D$9:$D1013, 'CF BEST'!$I$9:$I1013, B11,'CF BEST'!$F$9:$F1013, $O$5) -> 0 | P11: =SUMIFS('CF BEST'!$C$9:$C1013, 'CF BEST'!$I$9:$I1013, B11,'CF BEST'!$F$9:$F1013, $Q$5) -> 0 | Q11: =SUMIFS('CF BEST'!$D$9:$D1013, 'CF BEST'!$I$9:$I1013, B11,'CF BEST'!$F$9:$F1013, $Q$5) -> 0 | R11: =SUMIFS('CF BEST'!$C$9:$C1013, 'CF BEST'!$I$9:$I1013, B11,'CF BEST'!$F$9:$F1013, $S$5)+L11+N11+P11 -> 0 | S11: =SUMIFS('CF BEST'!$D$9:$D1013, 'CF BEST'!$I$9:$I1013, B11,'CF BEST'!$F$9:$F1013, $S$5)+M11+O11+Q11 -> 441075.07 | T11: =SUMIFS('CF BEST'!$C$9:$C1013, 'CF BEST'!$I$9:$I1013, B11,'CF BEST'!$F$9:$F1013, $U$5) -> 0 | U11: =SUMIFS('CF BEST'!$D$9:$D1013, 'CF BEST'!$I$9:$I1013, B11,'CF BEST'!$F$9:$F1013, $U$5) -> 0 | V11: =SUMIFS('CF BEST'!$C$9:$C1013, 'CF BEST'!$I$9:$I1013, B11,'CF BEST'!$F$9:$F1013, $W$5) -> 0 | W11: =SUMIFS('CF BEST'!$D$9:$D1013, 'CF BEST'!$I$9:$I1013, B11,'CF BEST'!$F$9:$F1013, $W$5) -> 0 | X11: =SUMIFS('CF BEST'!$C$9:$C1013, 'CF BEST'!$I$9:$I1013, B11,'CF BEST'!$F$9:$F1013, $Y$5) -> 0 | Y11: =SUMIFS('CF BEST'!$D$9:$D1013, 'CF BEST'!$I$9:$I1013, B11,'CF BEST'!$F$9:$F1013, $Y$5) -> 0 | Z11: =SUMIFS('CF BEST'!$C$9:$C1013, 'CF BEST'!$I$9:$I1013, B11,'CF BEST'!$F$9:$F1013, $AA$5)+T11+V11+X11 -> 0 | AA11: =SUMIFS('CF BEST'!$D$9:$D1013, 'CF BEST'!$I$9:$I1013, B11,'CF BEST'!$F$9:$F1013, $AA$5)+U11+W11+Y11 -> 0 | AB11: =SUMIFS('CF BEST'!$C$9:$C1013, 'CF BEST'!$I$9:$I1013, B11,'CF BEST'!$F$9:$F1013, $AC$5) -> 0 | AC11: =SUMIFS('CF BEST'!$D$9:$D1013, 'CF BEST'!$I$9:$I1013, B11,'CF BEST'!$F$9:$F1013, $AC$5) -> 0 | AD11: =SUMIFS('CF BEST'!$C$9:$C1013, 'CF BEST'!$I$9:$I1013, B11,'CF BEST'!$F$9:$F1013, $AE$5) -> 0 | AE11: =SUMIFS('CF BEST'!$D$9:$D1013, 'CF BEST'!$I$9:$I1013, B11,'CF BEST'!$F$9:$F1013, $AE$5) -> 0 | AF11: =SUMIFS('CF BEST'!$C$9:$C1013, 'CF BEST'!$I$9:$I1013, B11,'CF BEST'!$F$9:$F1013, $AG$5) -> 0 | AG11: =SUMIFS('CF BEST'!$D$9:$D1013, 'CF BEST'!$I$9:$I1013, B11,'CF BEST'!$F$9:$F1013, $AG$5) -> 0 | AH11: =SUMIFS('CF BEST'!$C$9:$C1013, 'CF BEST'!$I$9:$I1013, B11,'CF BEST'!$F$9:$F1013, $AI$5)+AB11+AD11+AF11 -> 0 | AI11: =SUMIFS('CF BEST'!$D$9:$D1013, 'CF BEST'!$I$9:$I1013, B11,'CF BEST'!$F$9:$F1013, $AI$5)+AC11+AE11+AG11 -> 0
A12: =C12/$C$7 -> 0.0072309304 | B12: БАННЕРЫ | C12: =K12+S12+AA12+AI12 -> 520500 | D12: =SUMIFS('CF BEST'!$C$9:$C1013, 'CF BEST'!$I$9:$I1013, B12,'CF BEST'!$F$9:$F1013, $E$5) -> 0 | E12: =SUMIFS('CF BEST'!$D$9:$D1013, 'CF BEST'!$I$9:$I1013, B12,'CF BEST'!$F$9:$F1013, $E$5) -> 140000 | F12: =SUMIFS('CF BEST'!$C$9:$C1013, 'CF BEST'!$I$9:$I1013, B12,'CF BEST'!$F$9:$F1013, $G$5) -> 0 | G12: =SUMIFS('CF BEST'!$D$9:$D1013, 'CF BEST'!$I$9:$I1013, B12,'CF BEST'!$F$9:$F1013, $G$5) -> 117000 | H12: =SUMIFS('CF BEST'!$C$9:$C1013, 'CF BEST'!$I$9:$I1013, B12,'CF BEST'!$F$9:$F1013, $I$5) -> 0 | I12: =SUMIFS('CF BEST'!$D$9:$D1013, 'CF BEST'!$I$9:$I1013, B12,'CF BEST'!$F$9:$F1013, $I$5) -> 143000 | J12: =SUMIFS('CF BEST'!$C$9:$C1013, 'CF BEST'!$I$9:$I1013, B12,'CF BEST'!$F$9:$F1013, $K$5)+D12+F12+H12 -> 0 | K12: =SUMIFS('CF BEST'!$D$9:$D1013, 'CF BEST'!$I$9:$I1013, B12,'CF BEST'!$F$9:$F1013, $K$5)+E12+G12+I12 -> 400000 | L12: =SUMIFS('CF BEST'!$C$9:$C1013, 'CF BEST'!$I$9:$I1013, B12,'CF BEST'!$F$9:$F1013, $M$5) -> 0 | M12: =SUMIFS('CF BEST'!$D$9:$D1013, 'CF BEST'!$I$9:$I1013, B12,'CF BEST'!$F$9:$F1013, $M$5) -> 120500 | N12: =SUMIFS('CF BEST'!$C$9:$C1013, 'CF BEST'!$I$9:$I1013, B12,'CF BEST'!$F$9:$F1013, $O$5) -> 0 | O12: =SUMIFS('CF BEST'!$D$9:$D1013, 'CF BEST'!$I$9:$I1013, B12,'CF BEST'!$F$9:$F1013, $O$5) -> 0 | P12: =SUMIFS('CF BEST'!$C$9:$C1013, 'CF BEST'!$I$9:$I1013, B12,'CF BEST'!$F$9:$F1013, $Q$5) -> 0 | Q12: =SUMIFS('CF BEST'!$D$9:$D1013, 'CF BEST'!$I$9:$I1013, B12,'CF BEST'!$F$9:$F1013, $Q$5) -> 0 | R12: =SUMIFS('CF BEST'!$C$9:$C1013, 'CF BEST'!$I$9:$I1013, B12,'CF BEST'!$F$9:$F1013, $S$5)+L12+N12+P12 -> 0 | S12: =SUMIFS('CF BEST'!$D$9:$D1013, 'CF BEST'!$I$9:$I1013, B12,'CF BEST'!$F$9:$F1013, $S$5)+M12+O12+Q12 -> 120500 | T12: =SUMIFS('CF BEST'!$C$9:$C1013, 'CF BEST'!$I$9:$I1013, B12,'CF BEST'!$F$9:$F1013, $U$5) -> 0 | U12: =SUMIFS('CF BEST'!$D$9:$D1013, 'CF BEST'!$I$9:$I1013, B12,'CF BEST'!$F$9:$F1013, $U$5) -> 0 | V12: =SUMIFS('CF BEST'!$C$9:$C1013, 'CF BEST'!$I$9:$I1013, B12,'CF BEST'!$F$9:$F1013, $W$5) -> 0 | W12: =SUMIFS('CF BEST'!$D$9:$D1013, 'CF BEST'!$I$9:$I1013, B12,'CF BEST'!$F$9:$F1013, $W$5) -> 0 | X12: =SUMIFS('CF BEST'!$C$9:$C1013, 'CF BEST'!$I$9:$I1013, B12,'CF BEST'!$F$9:$F1013, $Y$5) -> 0 | Y12: =SUMIFS('CF BEST'!$D$9:$D1013, 'CF BEST'!$I$9:$I1013, B12,'CF BEST'!$F$9:$F1013, $Y$5) -> 0 | Z12: =SUMIFS('CF BEST'!$C$9:$C1013, 'CF BEST'!$I$9:$I1013, B12,'CF BEST'!$F$9:$F1013, $AA$5)+T12+V12+X12 -> 0 | AA12: =SUMIFS('CF BEST'!$D$9:$D1013, 'CF BEST'!$I$9:$I1013, B12,'CF BEST'!$F$9:$F1013, $AA$5)+U12+W12+Y12 -> 0 | AB12: =SUMIFS('CF BEST'!$C$9:$C1013, 'CF BEST'!$I$9:$I1013, B12,'CF BEST'!$F$9:$F1013, $AC$5) -> 0 | AC12: =SUMIFS('CF BEST'!$D$9:$D1013, 'CF BEST'!$I$9:$I1013, B12,'CF BEST'!$F$9:$F1013, $AC$5) -> 0 | AD12: =SUMIFS('CF BEST'!$C$9:$C1013, 'CF BEST'!$I$9:$I1013, B12,'CF BEST'!$F$9:$F1013, $AE$5) -> 0 | AE12: =SUMIFS('CF BEST'!$D$9:$D1013, 'CF BEST'!$I$9:$I1013, B12,'CF BEST'!$F$9:$F1013, $AE$5) -> 0 | AF12: =SUMIFS('CF BEST'!$C$9:$C1013, 'CF BEST'!$I$9:$I1013, B12,'CF BEST'!$F$9:$F1013, $AG$5) -> 0 | AG12: =SUMIFS('CF BEST'!$D$9:$D1013, 'CF BEST'!$I$9:$I1013, B12,'CF BEST'!$F$9:$F1013, $AG$5) -> 0 | AH12: =SUMIFS('CF BEST'!$C$9:$C1013, 'CF BEST'!$I$9:$I1013, B12,'CF BEST'!$F$9:$F1013, $AI$5)+AB12+AD12+AF12 -> 0 | AI12: =SUMIFS('CF BEST'!$D$9:$D1013, 'CF BEST'!$I$9:$I1013, B12,'CF BEST'!$F$9:$F1013, $AI$5)+AC12+AE12+AG12 -> 0
A13: =C13/$C$7 -> 0.017496364 | B13: ОРД | C13: =K13+S13+AA13+AI13 -> 1259431 | D13: =SUMIFS('CF BEST'!$C$9:$C1013, 'CF BEST'!$I$9:$I1013, B13,'CF BEST'!$F$9:$F1013, $E$5) -> 0 | E13: =SUMIFS('CF BEST'!$D$9:$D1013, 'CF BEST'!$I$9:$I1013, B13,'CF BEST'!$F$9:$F1013, $E$5) -> 510511.04 | F13: =SUMIFS('CF BEST'!$C$9:$C1013, 'CF BEST'!$I$9:$I1013, B13,'CF BEST'!$F$9:$F1013, $G$5) -> 0 | G13: =SUMIFS('CF BEST'!$D$9:$D1013, 'CF BEST'!$I$9:$I1013, B13,'CF BEST'!$F$9:$F1013, $G$5) -> 56466.18 | H13: =SUMIFS('CF BEST'!$C$9:$C1013, 'CF BEST'!$I$9:$I1013, B13,'CF BEST'!$F$9:$F1013, $I$5) -> 0 | I13: =SUMIFS('CF BEST'!$D$9:$D1013, 'CF BEST'!$I$9:$I1013, B13,'CF BEST'!$F$9:$F1013, $I$5) -> 220838.1 | J13: =SUMIFS('CF BEST'!$C$9:$C1013, 'CF BEST'!$I$9:$I1013, B13,'CF BEST'!$F$9:$F1013, $K$5)+D13+F13+H13 -> 0 | K13: =SUMIFS('CF BEST'!$D$9:$D1013, 'CF BEST'!$I$9:$I1013, B13,'CF BEST'!$F$9:$F1013, $K$5)+E13+G13+I13 -> 787815.32 | L13: =SUMIFS('CF BEST'!$C$9:$C1013, 'CF BEST'!$I$9:$I1013, B13,'CF BEST'!$F$9:$F1013, $M$5) -> 0 | M13: =SUMIFS('CF BEST'!$D$9:$D1013, 'CF BEST'!$I$9:$I1013, B13,'CF BEST'!$F$9:$F1013, $M$5) -> 314484.06 | N13: =SUMIFS('CF BEST'!$C$9:$C1013, 'CF BEST'!$I$9:$I1013, B13,'CF BEST'!$F$9:$F1013, $O$5) -> 0 | O13: =SUMIFS('CF BEST'!$D$9:$D1013, 'CF BEST'!$I$9:$I1013, B13,'CF BEST'!$F$9:$F1013, $O$5) -> 157131.58 | P13: =SUMIFS('CF BEST'!$C$9:$C1013, 'CF BEST'!$I$9:$I1013, B13,'CF BEST'!$F$9:$F1013, $Q$5) -> 0 | Q13: =SUMIFS('CF BEST'!$D$9:$D1013, 'CF BEST'!$I$9:$I1013, B13,'CF BEST'!$F$9:$F1013, $Q$5) -> 0 | R13: =SUMIFS('CF BEST'!$C$9:$C1013, 'CF BEST'!$I$9:$I1013, B13,'CF BEST'!$F$9:$F1013, $S$5)+L13+N13+P13 -> 0 | S13: =SUMIFS('CF BEST'!$D$9:$D1013, 'CF BEST'!$I$9:$I1013, B13,'CF BEST'!$F$9:$F1013, $S$5)+M13+O13+Q13 -> 471615.64 | T13: =SUMIFS('CF BEST'!$C$9:$C1013, 'CF BEST'!$I$9:$I1013, B13,'CF BEST'!$F$9:$F1013, $U$5) -> 0 | U13: =SUMIFS('CF BEST'!$D$9:$D1013, 'CF BEST'!$I$9:$I1013, B13,'CF BEST'!$F$9:$F1013, $U$5) -> 0 | V13: =SUMIFS('CF BEST'!$C$9:$C1013, 'CF BEST'!$I$9:$I1013, B13,'CF BEST'!$F$9:$F1013, $W$5) -> 0 | W13: =SUMIFS('CF BEST'!$D$9:$D1013, 'CF BEST'!$I$9:$I1013, B13,'CF BEST'!$F$9:$F1013, $W$5) -> 0 | X13: =SUMIFS('CF BEST'!$C$9:$C1013, 'CF BEST'!$I$9:$I1013, B13,'CF BEST'!$F$9:$F1013, $Y$5) -> 0 | Y13: =SUMIFS('CF BEST'!$D$9:$D1013, 'CF BEST'!$I$9:$I1013, B13,'CF BEST'!$F$9:$F1013, $Y$5) -> 0 | Z13: =SUMIFS('CF BEST'!$C$9:$C1013, 'CF BEST'!$I$9:$I1013, B13,'CF BEST'!$F$9:$F1013, $AA$5)+T13+V13+X13 -> 0 | AA13: =SUMIFS('CF BEST'!$D$9:$D1013, 'CF BEST'!$I$9:$I1013, B13,'CF BEST'!$F$9:$F1013, $AA$5)+U13+W13+Y13 -> 0 | AB13: =SUMIFS('CF BEST'!$C$9:$C1013, 'CF BEST'!$I$9:$I1013, B13,'CF BEST'!$F$9:$F1013, $AC$5) -> 0 | AC13: =SUMIFS('CF BEST'!$D$9:$D1013, 'CF BEST'!$I$9:$I1013, B13,'CF BEST'!$F$9:$F1013, $AC$5) -> 0 | AD13: =SUMIFS('CF BEST'!$C$9:$C1013, 'CF BEST'!$I$9:$I1013, B13,'CF BEST'!$F$9:$F1013, $AE$5) -> 0 | AE13: =SUMIFS('CF BEST'!$D$9:$D1013, 'CF BEST'!$I$9:$I1013, B13,'CF BEST'!$F$9:$F1013, $AE$5) -> 0 | AF13: =SUMIFS('CF BEST'!$C$9:$C1013, 'CF BEST'!$I$9:$I1013, B13,'CF BEST'!$F$9:$F1013, $AG$5) -> 0 | AG13: =SUMIFS('CF BEST'!$D$9:$D1013, 'CF BEST'!$I$9:$I1013, B13,'CF BEST'!$F$9:$F1013, $AG$5) -> 0 | AH13: =SUMIFS('CF BEST'!$C$9:$C1013, 'CF BEST'!$I$9:$I1013, B13,'CF BEST'!$F$9:$F1013, $AI$5)+AB13+AD13+AF13 -> 0 | AI13: =SUMIFS('CF BEST'!$D$9:$D1013, 'CF BEST'!$I$9:$I1013, B13,'CF BEST'!$F$9:$F1013, $AI$5)+AC13+AE13+AG13 -> 0
A14: =C14/$C$7 -> 0.035681725 | B14: ПОДРЯДЧИКИ | C14: =K14+S14+AA14+AI14 -> 2568457.6 | D14: =SUMIFS('CF BEST'!$C$9:$C1013, 'CF BEST'!$I$9:$I1013, B14,'CF BEST'!$F$9:$F1013, $E$5) -> 0 | E14: =SUMIFS('CF BEST'!$D$9:$D1013, 'CF BEST'!$I$9:$I1013, B14,'CF BEST'!$F$9:$F1013, $E$5) -> 359279.44 | F14: =SUMIFS('CF BEST'!$C$9:$C1013, 'CF BEST'!$I$9:$I1013, B14,'CF BEST'!$F$9:$F1013, $G$5) -> 0 | G14: =SUMIFS('CF BEST'!$D$9:$D1013, 'CF BEST'!$I$9:$I1013, B14,'CF BEST'!$F$9:$F1013, $G$5) -> 664488.66 | H14: =SUMIFS('CF BEST'!$C$9:$C1013, 'CF BEST'!$I$9:$I1013, B14,'CF BEST'!$F$9:$F1013, $I$5) -> 0 | I14: =SUMIFS('CF BEST'!$D$9:$D1013, 'CF BEST'!$I$9:$I1013, B14,'CF BEST'!$F$9:$F1013, $I$5) -> 184185.32 | J14: =SUMIFS('CF BEST'!$C$9:$C1013, 'CF BEST'!$I$9:$I1013, B14,'CF BEST'!$F$9:$F1013, $K$5)+D14+F14+H14 -> 0 | K14: =SUMIFS('CF BEST'!$D$9:$D1013, 'CF BEST'!$I$9:$I1013, B14,'CF BEST'!$F$9:$F1013, $K$5)+E14+G14+I14 -> 1207953.4 | L14: =SUMIFS('CF BEST'!$C$9:$C1013, 'CF BEST'!$I$9:$I1013, B14,'CF BEST'!$F$9:$F1013, $M$5) -> 0 | M14: =SUMIFS('CF BEST'!$D$9:$D1013, 'CF BEST'!$I$9:$I1013, B14,'CF BEST'!$F$9:$F1013, $M$5) -> 1052953.8 | N14: =SUMIFS('CF BEST'!$C$9:$C1013, 'CF BEST'!$I$9:$I1013, B14,'CF BEST'!$F$9:$F1013, $O$5) -> 0 | O14: =SUMIFS('CF BEST'!$D$9:$D1013, 'CF BEST'!$I$9:$I1013, B14,'CF BEST'!$F$9:$F1013, $O$5) -> 307550.35 | P14: =SUMIFS('CF BEST'!$C$9:$C1013, 'CF BEST'!$I$9:$I1013, B14,'CF BEST'!$F$9:$F1013, $Q$5) -> 0 | Q14: =SUMIFS('CF BEST'!$D$9:$D1013, 'CF BEST'!$I$9:$I1013, B14,'CF BEST'!$F$9:$F1013, $Q$5) -> 0 | R14: =SUMIFS('CF BEST'!$C$9:$C1013, 'CF BEST'!$I$9:$I1013, B14,'CF BEST'!$F$9:$F1013, $S$5)+L14+N14+P14 -> 0 | S14: =SUMIFS('CF BEST'!$D$9:$D1013, 'CF BEST'!$I$9:$I1013, B14,'CF BEST'!$F$9:$F1013, $S$5)+M14+O14+Q14 -> 1360504.2 | T14: =SUMIFS('CF BEST'!$C$9:$C1013, 'CF BEST'!$I$9:$I1013, B14,'CF BEST'!$F$9:$F1013, $U$5) -> 0 | U14: =SUMIFS('CF BEST'!$D$9:$D1013, 'CF BEST'!$I$9:$I1013, B14,'CF BEST'!$F$9:$F1013, $U$5) -> 0 | V14: =SUMIFS('CF BEST'!$C$9:$C1013, 'CF BEST'!$I$9:$I1013, B14,'CF BEST'!$F$9:$F1013, $W$5) -> 0 | W14: =SUMIFS('CF BEST'!$D$9:$D1013, 'CF BEST'!$I$9:$I1013, B14,'CF BEST'!$F$9:$F1013, $W$5) -> 0 | X14: =SUMIFS('CF BEST'!$C$9:$C1013, 'CF BEST'!$I$9:$I1013, B14,'CF BEST'!$F$9:$F1013, $Y$5) -> 0 | Y14: =SUMIFS('CF BEST'!$D$9:$D1013, 'CF BEST'!$I$9:$I1013, B14,'CF BEST'!$F$9:$F1013, $Y$5) -> 0 | Z14: =SUMIFS('CF BEST'!$C$9:$C1013, 'CF BEST'!$I$9:$I1013, B14,'CF BEST'!$F$9:$F1013, $AA$5)+T14+V14+X14 -> 0 | AA14: =SUMIFS('CF BEST'!$D$9:$D1013, 'CF BEST'!$I$9:$I1013, B14,'CF BEST'!$F$9:$F1013, $AA$5)+U14+W14+Y14 -> 0 | AB14: =SUMIFS('CF BEST'!$C$9:$C1013, 'CF BEST'!$I$9:$I1013, B14,'CF BEST'!$F$9:$F1013, $AC$5) -> 0 | AC14: =SUMIFS('CF BEST'!$D$9:$D1013, 'CF BEST'!$I$9:$I1013, B14,'CF BEST'!$F$9:$F1013, $AC$5) -> 0 | AD14: =SUMIFS('CF BEST'!$C$9:$C1013, 'CF BEST'!$I$9:$I1013, B14,'CF BEST'!$F$9:$F1013, $AE$5) -> 0 | AE14: =SUMIFS('CF BEST'!$D$9:$D1013, 'CF BEST'!$I$9:$I1013, B14,'CF BEST'!$F$9:$F1013, $AE$5) -> 0 | AF14: =SUMIFS('CF BEST'!$C$9:$C1013, 'CF BEST'!$I$9:$I1013, B14,'CF BEST'!$F$9:$F1013, $AG$5) -> 0 | AG14: =SUMIFS('CF BEST'!$D$9:$D1013, 'CF BEST'!$I$9:$I1013, B14,'CF BEST'!$F$9:$F1013, $AG$5) -> 0 | AH14: =SUMIFS('CF BEST'!$C$9:$C1013, 'CF BEST'!$I$9:$I1013, B14,'CF BEST'!$F$9:$F1013, $AI$5)+AB14+AD14+AF14 -> 0 | AI14: =SUMIFS('CF BEST'!$D$9:$D1013, 'CF BEST'!$I$9:$I1013, B14,'CF BEST'!$F$9:$F1013, $AI$5)+AC14+AE14+AG14 -> 0
A15: =C15/$C$7 -> 0.31952385 | B15: СОТРУДНИКИ | C15: =SUM(C16:C21) -> 23000105 | D15: =SUM(D16:D21) -> 0 | E15: =SUM(E16:E21) -> 3154281.8 | F15: =SUM(F16:F21) -> 0 | G15: =SUM(G16:G21) -> 3888226.7 | H15: =SUM(H16:H21) -> 0 | I15: =SUM(I16:I21) -> 6541904.8 | J15: =SUM(J16:J21) -> 0 | ... AI15: =SUM(AI16:AI21) -> 0
A16: =C16/$C$7 -> 0.070140195 | B16: АВАНС | C16: =K16+S16+AA16+AI16 -> 5048862.2 | D16: =SUMIFS('CF BEST'!$C$9:$C1013, 'CF BEST'!$I$9:$I1013, B16,'CF BEST'!$F$9:$F1013, $E$5) -> 0 | E16: =SUMIFS('CF BEST'!$D$9:$D1013, 'CF BEST'!$I$9:$I1013, B16,'CF BEST'!$F$9:$F1013, $E$5) -> 0 | F16: =SUMIFS('CF BEST'!$C$9:$C1013, 'CF BEST'!$I$9:$I1013, B16,'CF BEST'!$F$9:$F1013, $G$5) -> 0 | G16: =SUMIFS('CF BEST'!$D$9:$D1013, 'CF BEST'!$I$9:$I1013, B16,'CF BEST'!$F$9:$F1013, $G$5) -> 1124709.7 | H16: =SUMIFS('CF BEST'!$C$9:$C1013, 'CF BEST'!$I$9:$I1013, B16,'CF BEST'!$F$9:$F1013, $I$5) -> 0 | I16: =SUMIFS('CF BEST'!$D$9:$D1013, 'CF BEST'!$I$9:$I1013, B16,'CF BEST'!$F$9:$F1013, $I$5) -> 1219879.6 | J16: =SUMIFS('CF BEST'!$C$9:$C1013, 'CF BEST'!$I$9:$I1013, B16,'CF BEST'!$F$9:$F1013, $K$5)+D16+F16+H16 -> 0 | K16: =SUMIFS('CF BEST'!$D$9:$D1013, 'CF BEST'!$I$9:$I1013, B16,'CF BEST'!$F$9:$F1013, $K$5)+E16+G16+I16 -> 2344589.3 | L16: =SUMIFS('CF BEST'!$C$9:$C1013, 'CF BEST'!$I$9:$I1013, B16,'CF BEST'!$F$9:$F1013, $M$5) -> 0 | M16: =SUMIFS('CF BEST'!$D$9:$D1013, 'CF BEST'!$I$9:$I1013, B16,'CF BEST'!$F$9:$F1013, $M$5) -> 1213990 | N16: =SUMIFS('CF BEST'!$C$9:$C1013, 'CF BEST'!$I$9:$I1013, B16,'CF BEST'!$F$9:$F1013, $O$5) -> 0 | O16: =SUMIFS('CF BEST'!$D$9:$D1013, 'CF BEST'!$I$9:$I1013, B16,'CF BEST'!$F$9:$F1013, $O$5) -> 1256867 | P16: =SUMIFS('CF BEST'!$C$9:$C1013, 'CF BEST'!$I$9:$I1013, B16,'CF BEST'!$F$9:$F1013, $Q$5) -> 0 | Q16: =SUMIFS('CF BEST'!$D$9:$D1013, 'CF BEST'!$I$9:$I1013, B16,'CF BEST'!$F$9:$F1013, $Q$5) -> 233415.92 | R16: =SUMIFS('CF BEST'!$C$9:$C1013, 'CF BEST'!$I$9:$I1013, B16,'CF BEST'!$F$9:$F1013, $S$5)+L16+N16+P16 -> 0 | S16: =SUMIFS('CF BEST'!$D$9:$D1013, 'CF BEST'!$I$9:$I1013, B16,'CF BEST'!$F$9:$F1013, $S$5)+M16+O16+Q16 -> 2704272.9 | T16: =SUMIFS('CF BEST'!$C$9:$C1013, 'CF BEST'!$I$9:$I1013, B16,'CF BEST'!$F$9:$F1013, $U$5) -> 0 | U16: =SUMIFS('CF BEST'!$D$9:$D1013, 'CF BEST'!$I$9:$I1013, B16,'CF BEST'!$F$9:$F1013, $U$5) -> 0 | V16: =SUMIFS('CF BEST'!$C$9:$C1013, 'CF BEST'!$I$9:$I1013, B16,'CF BEST'!$F$9:$F1013, $W$5) -> 0 | W16: =SUMIFS('CF BEST'!$D$9:$D1013, 'CF BEST'!$I$9:$I1013, B16,'CF BEST'!$F$9:$F1013, $W$5) -> 0 | X16: =SUMIFS('CF BEST'!$C$9:$C1013, 'CF BEST'!$I$9:$I1013, B16,'CF BEST'!$F$9:$F1013, $Y$5) -> 0 | Y16: =SUMIFS('CF BEST'!$D$9:$D1013, 'CF BEST'!$I$9:$I1013, B16,'CF BEST'!$F$9:$F1013, $Y$5) -> 0 | Z16: =SUMIFS('CF BEST'!$C$9:$C1013, 'CF BEST'!$I$9:$I1013, B16,'CF BEST'!$F$9:$F1013, $AA$5)+T16+V16+X16 -> 0 | AA16: =SUMIFS('CF BEST'!$D$9:$D1013, 'CF BEST'!$I$9:$I1013, B16,'CF BEST'!$F$9:$F1013, $AA$5)+U16+W16+Y16 -> 0 | AB16: =SUMIFS('CF BEST'!$C$9:$C1013, 'CF BEST'!$I$9:$I1013, B16,'CF BEST'!$F$9:$F1013, $AC$5) -> 0 | AC16: =SUMIFS('CF BEST'!$D$9:$D1013, 'CF BEST'!$I$9:$I1013, B16,'CF BEST'!$F$9:$F1013, $AC$5) -> 0 | AD16: =SUMIFS('CF BEST'!$C$9:$C1013, 'CF BEST'!$I$9:$I1013, B16,'CF BEST'!$F$9:$F1013, $AE$5) -> 0 | AE16: =SUMIFS('CF BEST'!$D$9:$D1013, 'CF BEST'!$I$9:$I1013, B16,'CF BEST'!$F$9:$F1013, $AE$5) -> 0 | AF16: =SUMIFS('CF BEST'!$C$9:$C1013, 'CF BEST'!$I$9:$I1013, B16,'CF BEST'!$F$9:$F1013, $AG$5) -> 0 | AG16: =SUMIFS('CF BEST'!$D$9:$D1013, 'CF BEST'!$I$9:$I1013, B16,'CF BEST'!$F$9:$F1013, $AG$5) -> 0 | AH16: =SUMIFS('CF BEST'!$C$9:$C1013, 'CF BEST'!$I$9:$I1013, B16,'CF BEST'!$F$9:$F1013, $AI$5)+AB16+AD16+AF16 -> 0 | AI16: =SUMIFS('CF BEST'!$D$9:$D1013, 'CF BEST'!$I$9:$I1013, B16,'CF BEST'!$F$9:$F1013, $AI$5)+AC16+AE16+AG16 -> 0
A17: =C17/$C$7 -> 0.13939586 | B17: ФОТ | C17: =K17+S17+AA17+AI17 -> 10034054 | D17: =SUMIFS('CF BEST'!$C$9:$C1013, 'CF BEST'!$I$9:$I1013, B17,'CF BEST'!$F$9:$F1013, $E$5) -> 0 | E17: =SUMIFS('CF BEST'!$D$9:$D1013, 'CF BEST'!$I$9:$I1013, B17,'CF BEST'!$F$9:$F1013, $E$5) -> 2046076.8 | F17: =SUMIFS('CF BEST'!$C$9:$C1013, 'CF BEST'!$I$9:$I1013, B17,'CF BEST'!$F$9:$F1013, $G$5) -> 0 | G17: =SUMIFS('CF BEST'!$D$9:$D1013, 'CF BEST'!$I$9:$I1013, B17,'CF BEST'!$F$9:$F1013, $G$5) -> 1973345.4 | H17: =SUMIFS('CF BEST'!$C$9:$C1013, 'CF BEST'!$I$9:$I1013, B17,'CF BEST'!$F$9:$F1013, $I$5) -> 0 | I17: =SUMIFS('CF BEST'!$D$9:$D1013, 'CF BEST'!$I$9:$I1013, B17,'CF BEST'!$F$9:$F1013, $I$5) -> 2009208.4 | J17: =SUMIFS('CF BEST'!$C$9:$C1013, 'CF BEST'!$I$9:$I1013, B17,'CF BEST'!$F$9:$F1013, $K$5)+D17+F17+H17 -> 0 | K17: =SUMIFS('CF BEST'!$D$9:$D1013, 'CF BEST'!$I$9:$I1013, B17,'CF BEST'!$F$9:$F1013, $K$5)+E17+G17+I17 -> 6028630.6 | L17: =SUMIFS('CF BEST'!$C$9:$C1013, 'CF BEST'!$I$9:$I1013, B17,'CF BEST'!$F$9:$F1013, $M$5) -> 0 | M17: =SUMIFS('CF BEST'!$D$9:$D1013, 'CF BEST'!$I$9:$I1013, B17,'CF BEST'!$F$9:$F1013, $M$5) -> 1897282.7 | N17: =SUMIFS('CF BEST'!$C$9:$C1013, 'CF BEST'!$I$9:$I1013, B17,'CF BEST'!$F$9:$F1013, $O$5) -> 0 | O17: =SUMIFS('CF BEST'!$D$9:$D1013, 'CF BEST'!$I$9:$I1013, B17,'CF BEST'!$F$9:$F1013, $O$5) -> 2074332.4 | P17: =SUMIFS('CF BEST'!$C$9:$C1013, 'CF BEST'!$I$9:$I1013, B17,'CF BEST'!$F$9:$F1013, $Q$5) -> 0 | Q17: =SUMIFS('CF BEST'!$D$9:$D1013, 'CF BEST'!$I$9:$I1013, B17,'CF BEST'!$F$9:$F1013, $Q$5) -> 33808.22 | R17: =SUMIFS('CF BEST'!$C$9:$C1013, 'CF BEST'!$I$9:$I1013, B17,'CF BEST'!$F$9:$F1013, $S$5)+L17+N17+P17 -> 0 | S17: =SUMIFS('CF BEST'!$D$9:$D1013, 'CF BEST'!$I$9:$I1013, B17,'CF BEST'!$F$9:$F1013, $S$5)+M17+O17+Q17 -> 4005423.3 | T17: =SUMIFS('CF BEST'!$C$9:$C1013, 'CF BEST'!$I$9:$I1013, B17,'CF BEST'!$F$9:$F1013, $U$5) -> 0 | U17: =SUMIFS('CF BEST'!$D$9:$D1013, 'CF BEST'!$I$9:$I1013, B17,'CF BEST'!$F$9:$F1013, $U$5) -> 0 | V17: =SUMIFS('CF BEST'!$C$9:$C1013, 'CF BEST'!$I$9:$I1013, B17,'CF BEST'!$F$9:$F1013, $W$5) -> 0 | W17: =SUMIFS('CF BEST'!$D$9:$D1013, 'CF BEST'!$I$9:$I1013, B17,'CF BEST'!$F$9:$F1013, $W$5) -> 0 | X17: =SUMIFS('CF BEST'!$C$9:$C1013, 'CF BEST'!$I$9:$I1013, B17,'CF BEST'!$F$9:$F1013, $Y$5) -> 0 | Y17: =SUMIFS('CF BEST'!$D$9:$D1013, 'CF BEST'!$I$9:$I1013, B17,'CF BEST'!$F$9:$F1013, $Y$5) -> 0 | Z17: =SUMIFS('CF BEST'!$C$9:$C1013, 'CF BEST'!$I$9:$I1013, B17,'CF BEST'!$F$9:$F1013, $AA$5)+T17+V17+X17 -> 0 | AA17: =SUMIFS('CF BEST'!$D$9:$D1013, 'CF BEST'!$I$9:$I1013, B17,'CF BEST'!$F$9:$F1013, $AA$5)+U17+W17+Y17 -> 0 | AB17: =SUMIFS('CF BEST'!$C$9:$C1013, 'CF BEST'!$I$9:$I1013, B17,'CF BEST'!$F$9:$F1013, $AC$5) -> 0 | AC17: =SUMIFS('CF BEST'!$D$9:$D1013, 'CF BEST'!$I$9:$I1013, B17,'CF BEST'!$F$9:$F1013, $AC$5) -> 0 | AD17: =SUMIFS('CF BEST'!$C$9:$C1013, 'CF BEST'!$I$9:$I1013, B17,'CF BEST'!$F$9:$F1013, $AE$5) -> 0 | AE17: =SUMIFS('CF BEST'!$D$9:$D1013, 'CF BEST'!$I$9:$I1013, B17,'CF BEST'!$F$9:$F1013, $AE$5) -> 0 | AF17: =SUMIFS('CF BEST'!$C$9:$C1013, 'CF BEST'!$I$9:$I1013, B17,'CF BEST'!$F$9:$F1013, $AG$5) -> 0 | AG17: =SUMIFS('CF BEST'!$D$9:$D1013, 'CF BEST'!$I$9:$I1013, B17,'CF BEST'!$F$9:$F1013, $AG$5) -> 0 | AH17: =SUMIFS('CF BEST'!$C$9:$C1013, 'CF BEST'!$I$9:$I1013, B17,'CF BEST'!$F$9:$F1013, $AI$5)+AB17+AD17+AF17 -> 0 | AI17: =SUMIFS('CF BEST'!$D$9:$D1013, 'CF BEST'!$I$9:$I1013, B17,'CF BEST'!$F$9:$F1013, $AI$5)+AC17+AE17+AG17 -> 0
A18: =C18/$C$7 -> 0.027992939 | B18: ПРЕМИЯ | C18: =K18+S18+AA18+AI18 -> 2015000 | D18: =SUMIFS('CF BEST'!$C$9:$C1013, 'CF BEST'!$I$9:$I1013, B18,'CF BEST'!$F$9:$F1013, $E$5) -> 0 | E18: =SUMIFS('CF BEST'!$D$9:$D1013, 'CF BEST'!$I$9:$I1013, B18,'CF BEST'!$F$9:$F1013, $E$5) -> 480000 | F18: =SUMIFS('CF BEST'!$C$9:$C1013, 'CF BEST'!$I$9:$I1013, B18,'CF BEST'!$F$9:$F1013, $G$5) -> 0 | G18: =SUMIFS('CF BEST'!$D$9:$D1013, 'CF BEST'!$I$9:$I1013, B18,'CF BEST'!$F$9:$F1013, $G$5) -> 400000 | H18: =SUMIFS('CF BEST'!$C$9:$C1013, 'CF BEST'!$I$9:$I1013, B18,'CF BEST'!$F$9:$F1013, $I$5) -> 0 | I18: =SUMIFS('CF BEST'!$D$9:$D1013, 'CF BEST'!$I$9:$I1013, B18,'CF BEST'!$F$9:$F1013, $I$5) -> 395000 | J18: =SUMIFS('CF BEST'!$C$9:$C1013, 'CF BEST'!$I$9:$I1013, B18,'CF BEST'!$F$9:$F1013, $K$5)+D18+F18+H18 -> 0 | K18: =SUMIFS('CF BEST'!$D$9:$D1013, 'CF BEST'!$I$9:$I1013, B18,'CF BEST'!$F$9:$F1013, $K$5)+E18+G18+I18 -> 1275000 | L18: =SUMIFS('CF BEST'!$C$9:$C1013, 'CF BEST'!$I$9:$I1013, B18,'CF BEST'!$F$9:$F1013, $M$5) -> 0 | M18: =SUMIFS('CF BEST'!$D$9:$D1013, 'CF BEST'!$I$9:$I1013, B18,'CF BEST'!$F$9:$F1013, $M$5) -> 380000 | N18: =SUMIFS('CF BEST'!$C$9:$C1013, 'CF BEST'!$I$9:$I1013, B18,'CF BEST'!$F$9:$F1013, $O$5) -> 0 | O18: =SUMIFS('CF BEST'!$D$9:$D1013, 'CF BEST'!$I$9:$I1013, B18,'CF BEST'!$F$9:$F1013, $O$5) -> 330000 | P18: =SUMIFS('CF BEST'!$C$9:$C1013, 'CF BEST'!$I$9:$I1013, B18,'CF BEST'!$F$9:$F1013, $Q$5) -> 0 | Q18: =SUMIFS('CF BEST'!$D$9:$D1013, 'CF BEST'!$I$9:$I1013, B18,'CF BEST'!$F$9:$F1013, $Q$5) -> 30000 | R18: =SUMIFS('CF BEST'!$C$9:$C1013, 'CF BEST'!$I$9:$I1013, B18,'CF BEST'!$F$9:$F1013, $S$5)+L18+N18+P18 -> 0 | S18: =SUMIFS('CF BEST'!$D$9:$D1013, 'CF BEST'!$I$9:$I1013, B18,'CF BEST'!$F$9:$F1013, $S$5)+M18+O18+Q18 -> 740000 | T18: =SUMIFS('CF BEST'!$C$9:$C1013, 'CF BEST'!$I$9:$I1013, B18,'CF BEST'!$F$9:$F1013, $U$5) -> 0 | U18: =SUMIFS('CF BEST'!$D$9:$D1013, 'CF BEST'!$I$9:$I1013, B18,'CF BEST'!$F$9:$F1013, $U$5) -> 0 | V18: =SUMIFS('CF BEST'!$C$9:$C1013, 'CF BEST'!$I$9:$I1013, B18,'CF BEST'!$F$9:$F1013, $W$5) -> 0 | W18: =SUMIFS('CF BEST'!$D$9:$D1013, 'CF BEST'!$I$9:$I1013, B18,'CF BEST'!$F$9:$F1013, $W$5) -> 0 | X18: =SUMIFS('CF BEST'!$C$9:$C1013, 'CF BEST'!$I$9:$I1013, B18,'CF BEST'!$F$9:$F1013, $Y$5) -> 0 | Y18: =SUMIFS('CF BEST'!$D$9:$D1013, 'CF BEST'!$I$9:$I1013, B18,'CF BEST'!$F$9:$F1013, $Y$5) -> 0 | Z18: =SUMIFS('CF BEST'!$C$9:$C1013, 'CF BEST'!$I$9:$I1013, B18,'CF BEST'!$F$9:$F1013, $AA$5)+T18+V18+X18 -> 0 | AA18: =SUMIFS('CF BEST'!$D$9:$D1013, 'CF BEST'!$I$9:$I1013, B18,'CF BEST'!$F$9:$F1013, $AA$5)+U18+W18+Y18 -> 0 | AB18: =SUMIFS('CF BEST'!$C$9:$C1013, 'CF BEST'!$I$9:$I1013, B18,'CF BEST'!$F$9:$F1013, $AC$5) -> 0 | AC18: =SUMIFS('CF BEST'!$D$9:$D1013, 'CF BEST'!$I$9:$I1013, B18,'CF BEST'!$F$9:$F1013, $AC$5) -> 0 | AD18: =SUMIFS('CF BEST'!$C$9:$C1013, 'CF BEST'!$I$9:$I1013, B18,'CF BEST'!$F$9:$F1013, $AE$5) -> 0 | AE18: =SUMIFS('CF BEST'!$D$9:$D1013, 'CF BEST'!$I$9:$I1013, B18,'CF BEST'!$F$9:$F1013, $AE$5) -> 0 | AF18: =SUMIFS('CF BEST'!$C$9:$C1013, 'CF BEST'!$I$9:$I1013, B18,'CF BEST'!$F$9:$F1013, $AG$5) -> 0 | AG18: =SUMIFS('CF BEST'!$D$9:$D1013, 'CF BEST'!$I$9:$I1013, B18,'CF BEST'!$F$9:$F1013, $AG$5) -> 0 | AH18: =SUMIFS('CF BEST'!$C$9:$C1013, 'CF BEST'!$I$9:$I1013, B18,'CF BEST'!$F$9:$F1013, $AI$5)+AB18+AD18+AF18 -> 0 | AI18: =SUMIFS('CF BEST'!$D$9:$D1013, 'CF BEST'!$I$9:$I1013, B18,'CF BEST'!$F$9:$F1013, $AI$5)+AC18+AE18+AG18 -> 0
A19: =C19/$C$7 -> 0.010000332 | B19: БОНУСЫ | C19: =K19+S19+AA19+AI19 -> 719848.3 | D19: =SUMIFS('CF BEST'!$C$9:$C1013, 'CF BEST'!$I$9:$I1013, B19,'CF BEST'!$F$9:$F1013, $E$5) -> 0 | E19: =SUMIFS('CF BEST'!$D$9:$D1013, 'CF BEST'!$I$9:$I1013, B19,'CF BEST'!$F$9:$F1013, $E$5) -> 0 | F19: =SUMIFS('CF BEST'!$C$9:$C1013, 'CF BEST'!$I$9:$I1013, B19,'CF BEST'!$F$9:$F1013, $G$5) -> 0 | G19: =SUMIFS('CF BEST'!$D$9:$D1013, 'CF BEST'!$I$9:$I1013, B19,'CF BEST'!$F$9:$F1013, $G$5) -> 0 | H19: =SUMIFS('CF BEST'!$C$9:$C1013, 'CF BEST'!$I$9:$I1013, B19,'CF BEST'!$F$9:$F1013, $I$5) -> 0 | I19: =SUMIFS('CF BEST'!$D$9:$D1013, 'CF BEST'!$I$9:$I1013, B19,'CF BEST'!$F$9:$F1013, $I$5) -> 85000 | J19: =SUMIFS('CF BEST'!$C$9:$C1013, 'CF BEST'!$I$9:$I1013, B19,'CF BEST'!$F$9:$F1013, $K$5)+D19+F19+H19 -> 0 | K19: =SUMIFS('CF BEST'!$D$9:$D1013, 'CF BEST'!$I$9:$I1013, B19,'CF BEST'!$F$9:$F1013, $K$5)+E19+G19+I19 -> 569848.3 | L19: =SUMIFS('CF BEST'!$C$9:$C1013, 'CF BEST'!$I$9:$I1013, B19,'CF BEST'!$F$9:$F1013, $M$5) -> 0 | M19: =SUMIFS('CF BEST'!$D$9:$D1013, 'CF BEST'!$I$9:$I1013, B19,'CF BEST'!$F$9:$F1013, $M$5) -> 150000 | N19: =SUMIFS('CF BEST'!$C$9:$C1013, 'CF BEST'!$I$9:$I1013, B19,'CF BEST'!$F$9:$F1013, $O$5) -> 0 | O19: =SUMIFS('CF BEST'!$D$9:$D1013, 'CF BEST'!$I$9:$I1013, B19,'CF BEST'!$F$9:$F1013, $O$5) -> 0 | P19: =SUMIFS('CF BEST'!$C$9:$C1013, 'CF BEST'!$I$9:$I1013, B19,'CF BEST'!$F$9:$F1013, $Q$5) -> 0 | Q19: =SUMIFS('CF BEST'!$D$9:$D1013, 'CF BEST'!$I$9:$I1013, B19,'CF BEST'!$F$9:$F1013, $Q$5) -> 0 | R19: =SUMIFS('CF BEST'!$C$9:$C1013, 'CF BEST'!$I$9:$I1013, B19,'CF BEST'!$F$9:$F1013, $S$5)+L19+N19+P19 -> 0 | S19: =SUMIFS('CF BEST'!$D$9:$D1013, 'CF BEST'!$I$9:$I1013, B19,'CF BEST'!$F$9:$F1013, $S$5)+M19+O19+Q19 -> 150000 | T19: =SUMIFS('CF BEST'!$C$9:$C1013, 'CF BEST'!$I$9:$I1013, B19,'CF BEST'!$F$9:$F1013, $U$5) -> 0 | U19: =SUMIFS('CF BEST'!$D$9:$D1013, 'CF BEST'!$I$9:$I1013, B19,'CF BEST'!$F$9:$F1013, $U$5) -> 0 | V19: =SUMIFS('CF BEST'!$C$9:$C1013, 'CF BEST'!$I$9:$I1013, B19,'CF BEST'!$F$9:$F1013, $W$5) -> 0 | W19: =SUMIFS('CF BEST'!$D$9:$D1013, 'CF BEST'!$I$9:$I1013, B19,'CF BEST'!$F$9:$F1013, $W$5) -> 0 | X19: =SUMIFS('CF BEST'!$C$9:$C1013, 'CF BEST'!$I$9:$I1013, B19,'CF BEST'!$F$9:$F1013, $Y$5) -> 0 | Y19: =SUMIFS('CF BEST'!$D$9:$D1013, 'CF BEST'!$I$9:$I1013, B19,'CF BEST'!$F$9:$F1013, $Y$5) -> 0 | Z19: =SUMIFS('CF BEST'!$C$9:$C1013, 'CF BEST'!$I$9:$I1013, B19,'CF BEST'!$F$9:$F1013, $AA$5)+T19+V19+X19 -> 0 | AA19: =SUMIFS('CF BEST'!$D$9:$D1013, 'CF BEST'!$I$9:$I1013, B19,'CF BEST'!$F$9:$F1013, $AA$5)+U19+W19+Y19 -> 0 | AB19: =SUMIFS('CF BEST'!$C$9:$C1013, 'CF BEST'!$I$9:$I1013, B19,'CF BEST'!$F$9:$F1013, $AC$5) -> 0 | AC19: =SUMIFS('CF BEST'!$D$9:$D1013, 'CF BEST'!$I$9:$I1013, B19,'CF BEST'!$F$9:$F1013, $AC$5) -> 0 | AD19: =SUMIFS('CF BEST'!$C$9:$C1013, 'CF BEST'!$I$9:$I1013, B19,'CF BEST'!$F$9:$F1013, $AE$5) -> 0 | AE19: =SUMIFS('CF BEST'!$D$9:$D1013, 'CF BEST'!$I$9:$I1013, B19,'CF BEST'!$F$9:$F1013, $AE$5) -> 0 | AF19: =SUMIFS('CF BEST'!$C$9:$C1013, 'CF BEST'!$I$9:$I1013, B19,'CF BEST'!$F$9:$F1013, $AG$5) -> 0 | AG19: =SUMIFS('CF BEST'!$D$9:$D1013, 'CF BEST'!$I$9:$I1013, B19,'CF BEST'!$F$9:$F1013, $AG$5) -> 0 | AH19: =SUMIFS('CF BEST'!$C$9:$C1013, 'CF BEST'!$I$9:$I1013, B19,'CF BEST'!$F$9:$F1013, $AI$5)+AB19+AD19+AF19 -> 0 | AI19: =SUMIFS('CF BEST'!$D$9:$D1013, 'CF BEST'!$I$9:$I1013, B19,'CF BEST'!$F$9:$F1013, $AI$5)+AC19+AE19+AG19 -> 0
A20: =C20/$C$7 -> 0.024355941 | B20: НАЛОГИ | НДФЛ | C20: =K20+S20+AA20+AI20 -> 1753200 | D20: =SUMIFS('CF BEST'!$C$9:$C1013, 'CF BEST'!$I$9:$I1013, B20,'CF BEST'!$F$9:$F1013, $E$5) -> 0 | E20: =SUMIFS('CF BEST'!$D$9:$D1013, 'CF BEST'!$I$9:$I1013, B20,'CF BEST'!$F$9:$F1013, $E$5) -> 0 | F20: =SUMIFS('CF BEST'!$C$9:$C1013, 'CF BEST'!$I$9:$I1013, B20,'CF BEST'!$F$9:$F1013, $G$5) -> 0 | G20: =SUMIFS('CF BEST'!$D$9:$D1013, 'CF BEST'!$I$9:$I1013, B20,'CF BEST'!$F$9:$F1013, $G$5) -> 367827 | H20: =SUMIFS('CF BEST'!$C$9:$C1013, 'CF BEST'!$I$9:$I1013, B20,'CF BEST'!$F$9:$F1013, $I$5) -> 0 | I20: =SUMIFS('CF BEST'!$D$9:$D1013, 'CF BEST'!$I$9:$I1013, B20,'CF BEST'!$F$9:$F1013, $I$5) -> 729894 | J20: =SUMIFS('CF BEST'!$C$9:$C1013, 'CF BEST'!$I$9:$I1013, B20,'CF BEST'!$F$9:$F1013, $K$5)+D20+F20+H20 -> 0 | K20: =SUMIFS('CF BEST'!$D$9:$D1013, 'CF BEST'!$I$9:$I1013, B20,'CF BEST'!$F$9:$F1013, $K$5)+E20+G20+I20 -> 1097721 | L20: =SUMIFS('CF BEST'!$C$9:$C1013, 'CF BEST'!$I$9:$I1013, B20,'CF BEST'!$F$9:$F1013, $M$5) -> 0 | M20: =SUMIFS('CF BEST'!$D$9:$D1013, 'CF BEST'!$I$9:$I1013, B20,'CF BEST'!$F$9:$F1013, $M$5) -> 181342 | N20: =SUMIFS('CF BEST'!$C$9:$C1013, 'CF BEST'!$I$9:$I1013, B20,'CF BEST'!$F$9:$F1013, $O$5) -> 0 | O20: =SUMIFS('CF BEST'!$D$9:$D1013, 'CF BEST'!$I$9:$I1013, B20,'CF BEST'!$F$9:$F1013, $O$5) -> 474137 | P20: =SUMIFS('CF BEST'!$C$9:$C1013, 'CF BEST'!$I$9:$I1013, B20,'CF BEST'!$F$9:$F1013, $Q$5) -> 0 | Q20: =SUMIFS('CF BEST'!$D$9:$D1013, 'CF BEST'!$I$9:$I1013, B20,'CF BEST'!$F$9:$F1013, $Q$5) -> 0 | R20: =SUMIFS('CF BEST'!$C$9:$C1013, 'CF BEST'!$I$9:$I1013, B20,'CF BEST'!$F$9:$F1013, $S$5)+L20+N20+P20 -> 0 | S20: =SUMIFS('CF BEST'!$D$9:$D1013, 'CF BEST'!$I$9:$I1013, B20,'CF BEST'!$F$9:$F1013, $S$5)+M20+O20+Q20 -> 655479 | T20: =SUMIFS('CF BEST'!$C$9:$C1013, 'CF BEST'!$I$9:$I1013, B20,'CF BEST'!$F$9:$F1013, $U$5) -> 0 | U20: =SUMIFS('CF BEST'!$D$9:$D1013, 'CF BEST'!$I$9:$I1013, B20,'CF BEST'!$F$9:$F1013, $U$5) -> 0 | V20: =SUMIFS('CF BEST'!$C$9:$C1013, 'CF BEST'!$I$9:$I1013, B20,'CF BEST'!$F$9:$F1013, $W$5) -> 0 | W20: =SUMIFS('CF BEST'!$D$9:$D1013, 'CF BEST'!$I$9:$I1013, B20,'CF BEST'!$F$9:$F1013, $W$5) -> 0 | X20: =SUMIFS('CF BEST'!$C$9:$C1013, 'CF BEST'!$I$9:$I1013, B20,'CF BEST'!$F$9:$F1013, $Y$5) -> 0 | Y20: =SUMIFS('CF BEST'!$D$9:$D1013, 'CF BEST'!$I$9:$I1013, B20,'CF BEST'!$F$9:$F1013, $Y$5) -> 0 | Z20: =SUMIFS('CF BEST'!$C$9:$C1013, 'CF BEST'!$I$9:$I1013, B20,'CF BEST'!$F$9:$F1013, $AA$5)+T20+V20+X20 -> 0 | AA20: =SUMIFS('CF BEST'!$D$9:$D1013, 'CF BEST'!$I$9:$I1013, B20,'CF BEST'!$F$9:$F1013, $AA$5)+U20+W20+Y20 -> 0 | AB20: =SUMIFS('CF BEST'!$C$9:$C1013, 'CF BEST'!$I$9:$I1013, B20,'CF BEST'!$F$9:$F1013, $AC$5) -> 0 | AC20: =SUMIFS('CF BEST'!$D$9:$D1013, 'CF BEST'!$I$9:$I1013, B20,'CF BEST'!$F$9:$F1013, $AC$5) -> 0 | AD20: =SUMIFS('CF BEST'!$C$9:$C1013, 'CF BEST'!$I$9:$I1013, B20,'CF BEST'!$F$9:$F1013, $AE$5) -> 0 | AE20: =SUMIFS('CF BEST'!$D$9:$D1013, 'CF BEST'!$I$9:$I1013, B20,'CF BEST'!$F$9:$F1013, $AE$5) -> 0 | AF20: =SUMIFS('CF BEST'!$C$9:$C1013, 'CF BEST'!$I$9:$I1013, B20,'CF BEST'!$F$9:$F1013, $AG$5) -> 0 | AG20: =SUMIFS('CF BEST'!$D$9:$D1013, 'CF BEST'!$I$9:$I1013, B20,'CF BEST'!$F$9:$F1013, $AG$5) -> 0 | AH20: =SUMIFS('CF BEST'!$C$9:$C1013, 'CF BEST'!$I$9:$I1013, B20,'CF BEST'!$F$9:$F1013, $AI$5)+AB20+AD20+AF20 -> 0 | AI20: =SUMIFS('CF BEST'!$D$9:$D1013, 'CF BEST'!$I$9:$I1013, B20,'CF BEST'!$F$9:$F1013, $AI$5)+AC20+AE20+AG20 -> 0
A21: =C21/$C$7 -> 0.047638578 | B21: НАЛОГИ | Страх.Взносы | C21: =K21+S21+AA21+AI21 -> 3429141 | D21: =SUMIFS('CF BEST'!$C$9:$C1013, 'CF BEST'!$I$9:$I1013, B21,'CF BEST'!$F$9:$F1013, $E$5) -> 0 | E21: =SUMIFS('CF BEST'!$D$9:$D1013, 'CF BEST'!$I$9:$I1013, B21,'CF BEST'!$F$9:$F1013, $E$5) -> 628205 | F21: =SUMIFS('CF BEST'!$C$9:$C1013, 'CF BEST'!$I$9:$I1013, B21,'CF BEST'!$F$9:$F1013, $G$5) -> 0 | G21: =SUMIFS('CF BEST'!$D$9:$D1013, 'CF BEST'!$I$9:$I1013, B21,'CF BEST'!$F$9:$F1013, $G$5) -> 22344.67 | H21: =SUMIFS('CF BEST'!$C$9:$C1013, 'CF BEST'!$I$9:$I1013, B21,'CF BEST'!$F$9:$F1013, $I$5) -> 0 | I21: =SUMIFS('CF BEST'!$D$9:$D1013, 'CF BEST'!$I$9:$I1013, B21,'CF BEST'!$F$9:$F1013, $I$5) -> 2102922.7 | J21: =SUMIFS('CF BEST'!$C$9:$C1013, 'CF BEST'!$I$9:$I1013, B21,'CF BEST'!$F$9:$F1013, $K$5)+D21+F21+H21 -> 0 | K21: =SUMIFS('CF BEST'!$D$9:$D1013, 'CF BEST'!$I$9:$I1013, B21,'CF BEST'!$F$9:$F1013, $K$5)+E21+G21+I21 -> 2753472.4 | L21: =SUMIFS('CF BEST'!$C$9:$C1013, 'CF BEST'!$I$9:$I1013, B21,'CF BEST'!$F$9:$F1013, $M$5) -> 0 | M21: =SUMIFS('CF BEST'!$D$9:$D1013, 'CF BEST'!$I$9:$I1013, B21,'CF BEST'!$F$9:$F1013, $M$5) -> 7270.73 | N21: =SUMIFS('CF BEST'!$C$9:$C1013, 'CF BEST'!$I$9:$I1013, B21,'CF BEST'!$F$9:$F1013, $O$5) -> 0 | O21: =SUMIFS('CF BEST'!$D$9:$D1013, 'CF BEST'!$I$9:$I1013, B21,'CF BEST'!$F$9:$F1013, $O$5) -> 668397.88 | P21: =SUMIFS('CF BEST'!$C$9:$C1013, 'CF BEST'!$I$9:$I1013, B21,'CF BEST'!$F$9:$F1013, $Q$5) -> 0 | Q21: =SUMIFS('CF BEST'!$D$9:$D1013, 'CF BEST'!$I$9:$I1013, B21,'CF BEST'!$F$9:$F1013, $Q$5) -> 0 | R21: =SUMIFS('CF BEST'!$C$9:$C1013, 'CF BEST'!$I$9:$I1013, B21,'CF BEST'!$F$9:$F1013, $S$5)+L21+N21+P21 -> 0 | S21: =SUMIFS('CF BEST'!$D$9:$D1013, 'CF BEST'!$I$9:$I1013, B21,'CF BEST'!$F$9:$F1013, $S$5)+M21+O21+Q21 -> 675668.61 | T21: =SUMIFS('CF BEST'!$C$9:$C1013, 'CF BEST'!$I$9:$I1013, B21,'CF BEST'!$F$9:$F1013, $U$5) -> 0 | U21: =SUMIFS('CF BEST'!$D$9:$D1013, 'CF BEST'!$I$9:$I1013, B21,'CF BEST'!$F$9:$F1013, $U$5) -> 0 | V21: =SUMIFS('CF BEST'!$C$9:$C1013, 'CF BEST'!$I$9:$I1013, B21,'CF BEST'!$F$9:$F1013, $W$5) -> 0 | W21: =SUMIFS('CF BEST'!$D$9:$D1013, 'CF BEST'!$I$9:$I1013, B21,'CF BEST'!$F$9:$F1013, $W$5) -> 0 | X21: =SUMIFS('CF BEST'!$C$9:$C1013, 'CF BEST'!$I$9:$I1013, B21,'CF BEST'!$F$9:$F1013, $Y$5) -> 0 | Y21: =SUMIFS('CF BEST'!$D$9:$D1013, 'CF BEST'!$I$9:$I1013, B21,'CF BEST'!$F$9:$F1013, $Y$5) -> 0 | Z21: =SUMIFS('CF BEST'!$C$9:$C1013, 'CF BEST'!$I$9:$I1013, B21,'CF BEST'!$F$9:$F1013, $AA$5)+T21+V21+X21 -> 0 | AA21: =SUMIFS('CF BEST'!$D$9:$D1013, 'CF BEST'!$I$9:$I1013, B21,'CF BEST'!$F$9:$F1013, $AA$5)+U21+W21+Y21 -> 0 | AB21: =SUMIFS('CF BEST'!$C$9:$C1013, 'CF BEST'!$I$9:$I1013, B21,'CF BEST'!$F$9:$F1013, $AC$5) -> 0 | AC21: =SUMIFS('CF BEST'!$D$9:$D1013, 'CF BEST'!$I$9:$I1013, B21,'CF BEST'!$F$9:$F1013, $AC$5) -> 0 | AD21: =SUMIFS('CF BEST'!$C$9:$C1013, 'CF BEST'!$I$9:$I1013, B21,'CF BEST'!$F$9:$F1013, $AE$5) -> 0 | AE21: =SUMIFS('CF BEST'!$D$9:$D1013, 'CF BEST'!$I$9:$I1013, B21,'CF BEST'!$F$9:$F1013, $AE$5) -> 0 | AF21: =SUMIFS('CF BEST'!$C$9:$C1013, 'CF BEST'!$I$9:$I1013, B21,'CF BEST'!$F$9:$F1013, $AG$5) -> 0 | AG21: =SUMIFS('CF BEST'!$D$9:$D1013, 'CF BEST'!$I$9:$I1013, B21,'CF BEST'!$F$9:$F1013, $AG$5) -> 0 | AH21: =SUMIFS('CF BEST'!$C$9:$C1013, 'CF BEST'!$I$9:$I1013, B21,'CF BEST'!$F$9:$F1013, $AI$5)+AB21+AD21+AF21 -> 0 | AI21: =SUMIFS('CF BEST'!$D$9:$D1013, 'CF BEST'!$I$9:$I1013, B21,'CF BEST'!$F$9:$F1013, $AI$5)+AC21+AE21+AG21 -> 0
A22: =C22/$C$7 -> 0.062019677 | B22: НАЛОГИ | C22: =K22+S22+AA22+AI22 -> 4464327.5 | D22: =SUMIFS('CF BEST'!$C$9:$C1013, 'CF BEST'!$I$9:$I1013, B22,'CF BEST'!$F$9:$F1013, $E$5) -> 0 | E22: =SUM(E23:E27) -> 0 | F22: =SUM(F23:F27) -> 0 | G22: =SUM(G23:G27) -> 181.17 | H22: =SUM(H23:H27) -> 0 | I22: =SUM(I23:I27) -> 7346 | J22: =SUM(J23:J27) -> 0 | K22: =SUM(K23:K27) -> 4358395.5 | L22: =SUM(L23:L27) -> 0 | ... AI22: =SUM(AI23:AI27) -> 0
